<?xml version="1.0" ?>
<!-- =================================================================================== -->
<!-- |    This document was autogenerated by xacro from mir100_mobile_robot.xacro      | -->
<!-- |    EDITING THIS FILE BY HAND IS NOT RECOMMENDED                                 | -->
<!-- =================================================================================== -->
<robot name="mir100_mobile_robot">
  <!-- #################### Materials #################### -->
  <!-- ################################################### -->
  <!-- ################################################### -->
  <!-- #################### Materials #################### -->
  <!-- ############# Shapes Inertials with Origin ############# -->
  <!-- ######################################################## -->
  <!-- ######################################################## -->
  <!-- ############# Shapes Inertials with Origin ############# -->
  <!-- ################# Properties ################ -->
  <!-- ############################################# -->
  <!-- ############################################# -->
  <!-- ################# Properties ################ -->
  <!-- #################### Macros ################### -->
  <!-- ############################################### -->
  <!-- ############################################### -->
  <!-- #################### Macros ################### -->
  <!-- ############## Macros ################## -->
  <!-- ######################################## -->
  <!-- ######################################## -->
  <!-- ############## Macros ################## -->
  <!-- ############## Macros ################## -->
  <!-- ######################################## -->
  <!-- These are to publish the state of the unactuated 
            joints, the caster wheels. -->
  <gazebo>
    <plugin filename="libgazebo_ros_joint_state_publisher.so" name="joint_state_publisher">
      <robotNamespace>/</robotNamespace>
      <jointName> MiR__base_fl_caster_rotation_joint, MiR__base_fl_caster_wheel_joint,
                                MiR__base_fr_caster_rotation_joint, MiR__base_fr_caster_wheel_joint,
                                MiR__base_bl_caster_rotation_joint, MiR__base_bl_caster_wheel_joint,
                                MiR__base_br_caster_rotation_joint, MiR__base_br_caster_wheel_joint</jointName>
      <updateRate>20.0</updateRate>
      <alwaysOn>true</alwaysOn>
    </plugin>
  </gazebo>
  <!-- ######################################## -->
  <!-- ############## Macros ################## -->
  <link name="MiR_footprint"/>
  <!-- #################### MiR100 ##################### -->
  <!-- ################################################# -->
  <!-- #################### URDF ################### -->
  <joint name="MiR__base_joint_fixed" type="fixed">
    <parent link="MiR_footprint"/>
    <child link="MiR_base_link"/>
    <origin rpy="0 0 0" xyz="0 0 0"/>
  </joint>
  <link name="MiR_base_link">
    <inertial>
      <mass value="58.0"/>
      <origin rpy="0 0 0" xyz="0.037646 0 0.20"/>
      <inertia ixx="2.0609325089599997" ixy="0.0" ixz="0.0" iyy="4.34999826" iyz="0.0" izz="5.54093111696"/>
    </inertial>
    <visual>
      <origin rpy="0 0 0" xyz="0.037646 0 0"/>
      <geometry>
        <mesh filename="package://mir100_mobile_base/mesh/visual/mir_100_base.stl"/>
      </geometry>
      <material name="white">
        <color rgba="1 1 1 1"/>
      </material>
    </visual>
    <collision>
      <origin rpy="0 0 0" xyz="0.037646 0 0"/>
      <geometry>
        <mesh filename="package://mir100_mobile_base/mesh/collision/mir_100_base.stl"/>
      </geometry>
    </collision>
  </link>
  <joint name="MiR__base_left_wheel_joint" type="continuous">
    <origin rpy="0 0 0" xyz="0.0 0.222604 0.0625"/>
    <parent link="MiR_base_link"/>
    <child link="MiR_left_wheel_link"/>
    <axis xyz="0 1 0"/>
    <limit effort="100" velocity="20.0"/>
  </joint>
  <link name="MiR_left_wheel_link">
    <inertial>
      <mass value="1.0"/>
      <origin rpy="1.5707963267948966 0 0" xyz="0 0 0"/>
      <inertia ixx="0.001061895408575" ixy="0.0" ixz="0.0" iyy="0.001061895408575" iyz="0.0" izz="0.001953125"/>
    </inertial>
    <visual>
      <origin rpy="0 0 0" xyz="0 0 0"/>
      <geometry>
        <mesh filename="package://mir100_mobile_base/mesh/visual/wheel.stl"/>
      </geometry>
      <material name="dark_grey">
        <color rgba="0.3 0.3 0.3 1"/>
      </material>
    </visual>
    <collision>
      <origin rpy="0 0 0" xyz="0 0 0"/>
      <geometry>
        <mesh filename="package://mir100_mobile_base/mesh/visual/wheel.stl"/>
      </geometry>
    </collision>
  </link>
  <joint name="MiR__base_right_wheel_joint" type="continuous">
    <origin rpy="0 0 0" xyz="0.0 -0.222604 0.0625"/>
    <parent link="MiR_base_link"/>
    <child link="MiR_right_wheel_link"/>
    <axis xyz="0 1 0"/>
    <limit effort="100" velocity="20.0"/>
  </joint>
  <link name="MiR_right_wheel_link">
    <inertial>
      <mass value="1.0"/>
      <origin rpy="1.5707963267948966 0 0" xyz="0 0 0"/>
      <inertia ixx="0.001061895408575" ixy="0.0" ixz="0.0" iyy="0.001061895408575" iyz="0.0" izz="0.001953125"/>
    </inertial>
    <visual>
      <origin rpy="0 0 0" xyz="0 0 0"/>
      <geometry>
        <mesh filename="package://mir100_mobile_base/mesh/visual/wheel.stl"/>
      </geometry>
      <material name="dark_grey">
        <color rgba="0.3 0.3 0.3 1"/>
      </material>
    </visual>
    <collision>
      <origin rpy="0 0 0" xyz="0 0 0"/>
      <geometry>
        <mesh filename="package://mir100_mobile_base/mesh/visual/wheel.stl"/>
      </geometry>
    </collision>
  </link>
  <joint name="MiR__base_fl_caster_rotation_joint" type="continuous">
    <origin rpy="0 0 0" xyz="0.341346 0.203 0.1565"/>
    <parent link="MiR_base_link"/>
    <child link="MiR_fl_caster_rotation_link"/>
    <axis xyz="0 0 1"/>
    <dynamics damping="0.01" friction="0.0"/>
  </joint>
  <link name="MiR_fl_caster_rotation_link">
    <inertial>
      <!-- <origin xyz="0 0 -0.042500000044" rpy="${0.5 * pi} ${24 * deg_to_rad} ${1.5 * pi}" /> -->
      <origin rpy="0.41887903200000004 0 1.5707963267948966 " xyz="0 0 -0.042500000044"/>
      <mass value="0.3097539019"/>
      <inertia ixx="0.0005844517978" ixy="0" ixz="0" iyy="0.00052872551237" iyz="0" izz="0.00017923555074"/>
    </inertial>
    <visual>
      <origin rpy="0 0 0" xyz="0 0 0"/>
      <geometry>
        <mesh filename="package://mir100_mobile_base/mesh/visual/caster_wheel_base.stl"/>
      </geometry>
      <material name="silver">
        <color rgba="0.79 0.82 0.93 1"/>
      </material>
    </visual>
    <collision>
      <origin rpy="0 0 0" xyz="0 0 0"/>
      <geometry>
        <mesh filename="package://mir100_mobile_base/mesh/collision/caster_wheel_base.stl"/>
      </geometry>
    </collision>
  </link>
  <joint name="MiR__base_fl_caster_wheel_joint" type="continuous">
    <origin rpy="0 0 0" xyz="-0.0382 0 -0.094"/>
    <parent link="MiR_fl_caster_rotation_link"/>
    <child link="MiR_fl_caster_wheel_link"/>
    <axis xyz="0 1 0"/>
  </joint>
  <link name="MiR_fl_caster_wheel_link">
    <inertial>
      <mass value="1.0"/>
      <origin rpy="1.5707963267948966 0 0" xyz="0 0 0"/>
      <inertia ixx="0.001061895408575" ixy="0.0" ixz="0.0" iyy="0.001061895408575" iyz="0.0" izz="0.001953125"/>
    </inertial>
    <visual>
      <origin rpy="0 0 0" xyz="0 0 0"/>
      <geometry>
        <mesh filename="package://mir100_mobile_base/mesh/visual/wheel.stl"/>
      </geometry>
      <material name="dark_grey">
        <color rgba="0.3 0.3 0.3 1"/>
      </material>
    </visual>
    <collision>
      <origin rpy="0 0 0" xyz="0 0 0"/>
      <geometry>
        <mesh filename="package://mir100_mobile_base/mesh/visual/wheel.stl"/>
      </geometry>
    </collision>
  </link>
  <joint name="MiR__base_fr_caster_rotation_joint" type="continuous">
    <origin rpy="0 0 0" xyz="0.341346 -0.203 0.1565"/>
    <parent link="MiR_base_link"/>
    <child link="MiR_fr_caster_rotation_link"/>
    <axis xyz="0 0 1"/>
    <dynamics damping="0.01" friction="0.0"/>
  </joint>
  <link name="MiR_fr_caster_rotation_link">
    <inertial>
      <!-- <origin xyz="0 0 -0.042500000044" rpy="${0.5 * pi} ${24 * deg_to_rad} ${1.5 * pi}" /> -->
      <origin rpy="0.41887903200000004 0 1.5707963267948966 " xyz="0 0 -0.042500000044"/>
      <mass value="0.3097539019"/>
      <inertia ixx="0.0005844517978" ixy="0" ixz="0" iyy="0.00052872551237" iyz="0" izz="0.00017923555074"/>
    </inertial>
    <visual>
      <origin rpy="0 0 0" xyz="0 0 0"/>
      <geometry>
        <mesh filename="package://mir100_mobile_base/mesh/visual/caster_wheel_base.stl"/>
      </geometry>
      <material name="silver">
        <color rgba="0.79 0.82 0.93 1"/>
      </material>
    </visual>
    <collision>
      <origin rpy="0 0 0" xyz="0 0 0"/>
      <geometry>
        <mesh filename="package://mir100_mobile_base/mesh/collision/caster_wheel_base.stl"/>
      </geometry>
    </collision>
  </link>
  <joint name="MiR__base_fr_caster_wheel_joint" type="continuous">
    <origin rpy="0 0 0" xyz="-0.0382 0 -0.094"/>
    <parent link="MiR_fr_caster_rotation_link"/>
    <child link="MiR_fr_caster_wheel_link"/>
    <axis xyz="0 1 0"/>
  </joint>
  <link name="MiR_fr_caster_wheel_link">
    <inertial>
      <mass value="1.0"/>
      <origin rpy="1.5707963267948966 0 0" xyz="0 0 0"/>
      <inertia ixx="0.001061895408575" ixy="0.0" ixz="0.0" iyy="0.001061895408575" iyz="0.0" izz="0.001953125"/>
    </inertial>
    <visual>
      <origin rpy="0 0 0" xyz="0 0 0"/>
      <geometry>
        <mesh filename="package://mir100_mobile_base/mesh/visual/wheel.stl"/>
      </geometry>
      <material name="dark_grey">
        <color rgba="0.3 0.3 0.3 1"/>
      </material>
    </visual>
    <collision>
      <origin rpy="0 0 0" xyz="0 0 0"/>
      <geometry>
        <mesh filename="package://mir100_mobile_base/mesh/visual/wheel.stl"/>
      </geometry>
    </collision>
  </link>
  <joint name="MiR__base_bl_caster_rotation_joint" type="continuous">
    <origin rpy="0 0 0" xyz="-0.270154 0.203 0.1565"/>
    <parent link="MiR_base_link"/>
    <child link="MiR_bl_caster_rotation_link"/>
    <axis xyz="0 0 1"/>
    <dynamics damping="0.01" friction="0.0"/>
  </joint>
  <link name="MiR_bl_caster_rotation_link">
    <inertial>
      <!-- <origin xyz="0 0 -0.042500000044" rpy="${0.5 * pi} ${24 * deg_to_rad} ${1.5 * pi}" /> -->
      <origin rpy="0.41887903200000004 0 1.5707963267948966 " xyz="0 0 -0.042500000044"/>
      <mass value="0.3097539019"/>
      <inertia ixx="0.0005844517978" ixy="0" ixz="0" iyy="0.00052872551237" iyz="0" izz="0.00017923555074"/>
    </inertial>
    <visual>
      <origin rpy="0 0 0" xyz="0 0 0"/>
      <geometry>
        <mesh filename="package://mir100_mobile_base/mesh/visual/caster_wheel_base.stl"/>
      </geometry>
      <material name="silver">
        <color rgba="0.79 0.82 0.93 1"/>
      </material>
    </visual>
    <collision>
      <origin rpy="0 0 0" xyz="0 0 0"/>
      <geometry>
        <mesh filename="package://mir100_mobile_base/mesh/collision/caster_wheel_base.stl"/>
      </geometry>
    </collision>
  </link>
  <joint name="MiR__base_bl_caster_wheel_joint" type="continuous">
    <origin rpy="0 0 0" xyz="-0.0382 0 -0.094"/>
    <parent link="MiR_bl_caster_rotation_link"/>
    <child link="MiR_bl_caster_wheel_link"/>
    <axis xyz="0 1 0"/>
  </joint>
  <link name="MiR_bl_caster_wheel_link">
    <inertial>
      <mass value="1.0"/>
      <origin rpy="1.5707963267948966 0 0" xyz="0 0 0"/>
      <inertia ixx="0.001061895408575" ixy="0.0" ixz="0.0" iyy="0.001061895408575" iyz="0.0" izz="0.001953125"/>
    </inertial>
    <visual>
      <origin rpy="0 0 0" xyz="0 0 0"/>
      <geometry>
        <mesh filename="package://mir100_mobile_base/mesh/visual/wheel.stl"/>
      </geometry>
      <material name="dark_grey">
        <color rgba="0.3 0.3 0.3 1"/>
      </material>
    </visual>
    <collision>
      <origin rpy="0 0 0" xyz="0 0 0"/>
      <geometry>
        <mesh filename="package://mir100_mobile_base/mesh/visual/wheel.stl"/>
      </geometry>
    </collision>
  </link>
  <joint name="MiR__base_br_caster_rotation_joint" type="continuous">
    <origin rpy="0 0 0" xyz="-0.270154 -0.203 0.1565"/>
    <parent link="MiR_base_link"/>
    <child link="MiR_br_caster_rotation_link"/>
    <axis xyz="0 0 1"/>
    <dynamics damping="0.01" friction="0.0"/>
  </joint>
  <link name="MiR_br_caster_rotation_link">
    <inertial>
      <!-- <origin xyz="0 0 -0.042500000044" rpy="${0.5 * pi} ${24 * deg_to_rad} ${1.5 * pi}" /> -->
      <origin rpy="0.41887903200000004 0 1.5707963267948966 " xyz="0 0 -0.042500000044"/>
      <mass value="0.3097539019"/>
      <inertia ixx="0.0005844517978" ixy="0" ixz="0" iyy="0.00052872551237" iyz="0" izz="0.00017923555074"/>
    </inertial>
    <visual>
      <origin rpy="0 0 0" xyz="0 0 0"/>
      <geometry>
        <mesh filename="package://mir100_mobile_base/mesh/visual/caster_wheel_base.stl"/>
      </geometry>
      <material name="silver">
        <color rgba="0.79 0.82 0.93 1"/>
      </material>
    </visual>
    <collision>
      <origin rpy="0 0 0" xyz="0 0 0"/>
      <geometry>
        <mesh filename="package://mir100_mobile_base/mesh/collision/caster_wheel_base.stl"/>
      </geometry>
    </collision>
  </link>
  <joint name="MiR__base_br_caster_wheel_joint" type="continuous">
    <origin rpy="0 0 0" xyz="-0.0382 0 -0.094"/>
    <parent link="MiR_br_caster_rotation_link"/>
    <child link="MiR_br_caster_wheel_link"/>
    <axis xyz="0 1 0"/>
  </joint>
  <link name="MiR_br_caster_wheel_link">
    <inertial>
      <mass value="1.0"/>
      <origin rpy="1.5707963267948966 0 0" xyz="0 0 0"/>
      <inertia ixx="0.001061895408575" ixy="0.0" ixz="0.0" iyy="0.001061895408575" iyz="0.0" izz="0.001953125"/>
    </inertial>
    <visual>
      <origin rpy="0 0 0" xyz="0 0 0"/>
      <geometry>
        <mesh filename="package://mir100_mobile_base/mesh/visual/wheel.stl"/>
      </geometry>
      <material name="dark_grey">
        <color rgba="0.3 0.3 0.3 1"/>
      </material>
    </visual>
    <collision>
      <origin rpy="0 0 0" xyz="0 0 0"/>
      <geometry>
        <mesh filename="package://mir100_mobile_base/mesh/visual/wheel.stl"/>
      </geometry>
    </collision>
  </link>
  <joint name="MiR__base_to_surface_joint_fixed" type="fixed">
    <origin rpy="0 0 0" xyz="0.037646 0 0.352"/>
    <parent link="MiR_base_link"/>
    <child link="MiR_surface"/>
    <axis xyz="0 0 1"/>
  </joint>
  <link name="MiR_surface"/>
  <!-- IMU -->
  <joint name="MiR__base_to_imu_joint_fixed" type="fixed">
    <parent link="MiR_base_link"/>
    <child link="MiR_imu_link"/>
    <origin rpy="0 0 0" xyz="0.0 0.0 0.25"/>
    <!-- same as real MiR -->
  </joint>
  <link name="MiR_imu_link"/>
  <!-- Create an alias for imu_link. This is necessary because the real MiR's
                    TF has imu_link, but the imu_data topic is published in the imu_frame
                    frame. -->
  <joint name="MiR__imu_link_to_imu_frame_joint_fixed" type="fixed">
    <parent link="MiR_imu_link"/>
    <child link="MiR_imu_frame"/>
    <origin rpy="0 0 0" xyz="0 0 0"/>
  </joint>
  <link name="MiR_imu_frame"/>
  <!-- Laser scanners -->
  <link name="MiR_front_laser_link">
    <visual>
      <origin rpy="3.141592653589793 0 0" xyz="0.0 0.0 0.0"/>
      <geometry>
        <mesh filename="package://mir100_mobile_base/mesh/visual/sick_lms-100.stl"/>
      </geometry>
      <material name="black">
        <color rgba="0.1 0.1 0.1 1"/>
      </material>
    </visual>
    <collision>
      <origin rpy="3.141592653589793 0 0" xyz="0.0 0.0 0.0"/>
      <geometry>
        <mesh filename="package://mir100_mobile_base/mesh/visual/sick_lms-100.stl"/>
      </geometry>
    </collision>
    <inertial>
      <mass value="2.0"/>
      <origin xyz="0 0 0"/>
      <inertia ixx="0.009708329449999999" ixy="0.0" ixz="0.0" iyy="0.0097601627626" iyz="0.0" izz="0.0080601634426"/>
    </inertial>
  </link>
  <joint name="MiR__base_to_front_laser_joint_fixed" type="fixed">
    <parent link="MiR_base_link"/>
    <child link="MiR_front_laser_link"/>
    <origin rpy="0.0 0.0 0.7853981633974483" xyz="0.4288 0.2358 0.1914"/>
    <!-- from visually matching up the meshes of the MiR and the laser scanner -->
  </joint>
  <link name="MiR_back_laser_link">
    <visual>
      <origin rpy="3.141592653589793 0 0" xyz="0.0 0.0 0.0"/>
      <geometry>
        <mesh filename="package://mir100_mobile_base/mesh/visual/sick_lms-100.stl"/>
      </geometry>
      <material name="black">
        <color rgba="0.1 0.1 0.1 1"/>
      </material>
    </visual>
    <collision>
      <origin rpy="3.141592653589793 0 0" xyz="0.0 0.0 0.0"/>
      <geometry>
        <mesh filename="package://mir100_mobile_base/mesh/visual/sick_lms-100.stl"/>
      </geometry>
    </collision>
    <inertial>
      <mass value="2.0"/>
      <origin xyz="0 0 0"/>
      <inertia ixx="0.009708329449999999" ixy="0.0" ixz="0.0" iyy="0.0097601627626" iyz="0.0" izz="0.0080601634426"/>
    </inertial>
  </link>
  <joint name="Mir__base_to_back_laser_joint_fixed" type="fixed">
    <parent link="MiR_base_link"/>
    <child link="MiR_back_laser_link"/>
    <origin rpy="0.0 0.0 -2.356194490192345" xyz="-0.3548 -0.2352 0.1914"/>
    <!-- from visually matching up the meshes of the MiR and the laser scanner -->
  </joint>
  <!-- Ultrasound sensors -->
  <link name="MiR_right_us_frame"/>
  <joint name="MiR__base_to_right_us_joint_fixed" type="fixed">
    <parent link="MiR_base_link"/>
    <child link="MiR_right_us_frame"/>
    <origin rpy="0 0 0" xyz="0.45 -0.12 0.16 "/>
    <!-- from visually matching to the mesh of the MiR -->
  </joint>
  <link name="MiR_left_us_frame"/>
  <joint name="MiR__base_to_left_us_joint_fixed" type="fixed">
    <parent link="MiR_base_link"/>
    <child link="MiR_left_us_frame"/>
    <origin rpy="0 0 0" xyz="0.45 0.12 0.16 "/>
    <!-- from visually matching to the mesh of the MiR -->
  </joint>
  <!-- #################### URDF ################### -->
  <!-- ############## Transmissions ################ -->
  <transmission name="MiR_left_wheel_trans">
    <type>transmission_interface/SimpleTransmission</type>
    <joint name="MiR__base_left_wheel_joint">
      <hardwareInterface>hardware_interface/VelocityJointInterface</hardwareInterface>
    </joint>
    <actuator name="MiR__base_left_wheel_motor">
      <hardwareInterface>hardware_interface/VelocityJointInterface</hardwareInterface>
      <mechanicalReduction>1</mechanicalReduction>
    </actuator>
  </transmission>
  <transmission name="MiR_right_wheel_trans">
    <type>transmission_interface/SimpleTransmission</type>
    <joint name="MiR__base_right_wheel_joint">
      <hardwareInterface>hardware_interface/VelocityJointInterface</hardwareInterface>
    </joint>
    <actuator name="MiR__base_right_wheel_motor">
      <hardwareInterface>hardware_interface/VelocityJointInterface</hardwareInterface>
      <mechanicalReduction>1</mechanicalReduction>
    </actuator>
  </transmission>
  <!-- ############## Transmissions ################ -->
  <!-- ############## Gazebo ####################### -->
  <gazebo reference="MiR_left_wheel_link">
    <mu1 value="200"/>
    <mu2 value="200"/>
    <kp value="10000000.0"/>
    <kd value="1.0"/>
    <minDepth>0.01</minDepth>
  </gazebo>
  <gazebo reference="MiR_right_wheel_link">
    <mu1 value="200"/>
    <mu2 value="200"/>
    <kp value="10000000.0"/>
    <kd value="1.0"/>
    <minDepth>0.01</minDepth>
  </gazebo>
  <gazebo reference="MiR_fl_caster_wheel_link">
    <mu1 value="1"/>
    <mu2 value="1"/>
    <kp value="10000000.0"/>
    <kd value="1.0"/>
    <minDepth>0.01</minDepth>
  </gazebo>
  <gazebo reference="MiR_fr_caster_wheel_link">
    <mu1 value="1"/>
    <mu2 value="1"/>
    <kp value="10000000.0"/>
    <kd value="1.0"/>
    <minDepth>0.01</minDepth>
  </gazebo>
  <gazebo reference="MiR_bl_caster_wheel_link">
    <mu1 value="1"/>
    <mu2 value="1"/>
    <kp value="10000000.0"/>
    <kd value="1.0"/>
    <minDepth>0.01</minDepth>
  </gazebo>
  <gazebo reference="MiR_br_caster_wheel_link">
    <mu1 value="1"/>
    <mu2 value="1"/>
    <kp value="10000000.0"/>
    <kd value="1.0"/>
    <minDepth>0.01</minDepth>
  </gazebo>
  <gazebo>
    <plugin filename="libgazebo_ros_diff_drive.so" name="diff_drive_controller">
      <legacyMode>false</legacyMode>
      <alwaysOn>true</alwaysOn>
      <updateRate>1000.0</updateRate>
      <leftJoint>MiR__base_left_wheel_joint</leftJoint>
      <rightJoint>MiR__base_right_wheel_joint</rightJoint>
      <wheelSeparation>0.445208</wheelSeparation>
      <wheelDiameter>0.125</wheelDiameter>
      <wheelTorque>10</wheelTorque>
      <publishTf>false</publishTf>
      <odometryFrame>odom_frame</odometryFrame>
      <commandTopic>MiR/controller/cmd_vel</commandTopic>
      <odometryTopic>odom_topic</odometryTopic>
      <robotBaseFrame>MiR_footprint</robotBaseFrame>
      <wheelAcceleration>2.8</wheelAcceleration>
      <publishWheelJointState>true</publishWheelJointState>
      <publishWheelTF>false</publishWheelTF>
      <odometrySource>world</odometrySource>
      <rosDebugLevel>Debug</rosDebugLevel>
    </plugin>
  </gazebo>
  <gazebo reference="MiR_right_wheel_link">
    <material>Gazebo/DarkGrey</material>
    <turnGravityOff>false</turnGravityOff>
    <selfCollide>true</selfCollide>
  </gazebo>
  <gazebo reference="MiR_left_wheel_link">
    <material>Gazebo/DarkGrey</material>
    <turnGravityOff>false</turnGravityOff>
    <selfCollide>true</selfCollide>
  </gazebo>
  <gazebo reference="MiR_fl_caster_rotation_link">
    <material>Gazebo/Grey</material>
    <turnGravityOff>false</turnGravityOff>
    <selfCollide>true</selfCollide>
  </gazebo>
  <gazebo reference="MiR_fr_caster_rotation_link">
    <material>Gazebo/Grey</material>
    <turnGravityOff>false</turnGravityOff>
    <selfCollide>true</selfCollide>
  </gazebo>
  <gazebo reference="MiR_bl_caster_rotation_link">
    <material>Gazebo/Grey</material>
    <turnGravityOff>false</turnGravityOff>
    <selfCollide>true</selfCollide>
  </gazebo>
  <gazebo reference="MiR_br_caster_rotation_link">
    <material>Gazebo/Grey</material>
    <turnGravityOff>false</turnGravityOff>
    <selfCollide>true</selfCollide>
  </gazebo>
  <gazebo reference="MiR_front_laser_link">
    <material>Gazebo/FlatBlack</material>
    <turnGravityOff>false</turnGravityOff>
    <selfCollide>true</selfCollide>
    <sensor name="MiR__front_lase_link" type="ray">
      <pose>0 0 0 0 0 0</pose>
      <visualize>false</visualize>
      <update_rate>12.5</update_rate>
      <ray>
        <scan>
          <horizontal>
            <samples>541</samples>
            <resolution>1</resolution>
            <!-- has to be 1; actual resolution will be computed from number of samples + min_angle/max_angle -->
            <min_angle>-2.35619449615</min_angle>
            <max_angle>2.35619449615</max_angle>
          </horizontal>
        </scan>
        <range>
          <min>0.05</min>
          <max>29.0</max>
          <resolution>0.01</resolution>
        </range>
        <noise>
          <type>gaussian</type>
          <!-- Noise parameters based on published spec for S300 achieving
                                "+-29mm" accuracy at range < 3m (~0.01 of the range) at
                                1 sigma. -->
          <mean>0.0</mean>
          <stddev>0.01</stddev>
        </noise>
      </ray>
      <plugin filename="libgazebo_ros_laser.so" name="gazebo_ros_MiR__front_lase_link_controller">
        <frameName>MiR_front_laser_link</frameName>
        <topicName>/f_scan</topicName>
      </plugin>
    </sensor>
  </gazebo>
  <gazebo reference="MiR_back_laser_link">
    <material>Gazebo/FlatBlack</material>
    <turnGravityOff>false</turnGravityOff>
    <selfCollide>true</selfCollide>
    <sensor name="MiR__back_lase_link" type="ray">
      <pose>0 0 0 0 0 0</pose>
      <visualize>false</visualize>
      <update_rate>12.5</update_rate>
      <ray>
        <scan>
          <horizontal>
            <samples>541</samples>
            <resolution>1</resolution>
            <!-- has to be 1; actual resolution will be computed from number of samples + min_angle/max_angle -->
            <min_angle>-2.35619449615</min_angle>
            <max_angle>2.35619449615</max_angle>
          </horizontal>
        </scan>
        <range>
          <min>0.05</min>
          <max>29.0</max>
          <resolution>0.01</resolution>
        </range>
        <noise>
          <type>gaussian</type>
          <!-- Noise parameters based on published spec for S300 achieving
                            "+-29mm" accuracy at range < 3m (~0.01 of the range) at
                            1 sigma. -->
          <mean>0.0</mean>
          <stddev>0.01</stddev>
        </noise>
      </ray>
      <plugin filename="libgazebo_ros_laser.so" name="gazebo_ros_MiR__back_lase_link_controller">
        <frameName>MiR_back_laser_link</frameName>
        <topicName>/b_scan</topicName>
      </plugin>
    </sensor>
  </gazebo>
  <gazebo reference="MiR_base_link">
    <material>Gazebo/Grey</material>
    <turnGravityOff>false</turnGravityOff>
    <selfCollide>true</selfCollide>
  </gazebo>
  <gazebo>
    <plugin filename="libgazebo_ros_p3d.so" name="p3d_base_controller">
      <alwaysOn>true</alwaysOn>
      <updateRate>20.0</updateRate>
      <bodyName>MiR_base_link</bodyName>
      <topicName>odom_topic</topicName>
      <gaussianNoise>0.01</gaussianNoise>
      <frameName>MiR_footprint</frameName>
      <xyzOffsets>0 0 0</xyzOffsets>
      <rpyOffsets>0 0 0</rpyOffsets>
    </plugin>
  </gazebo>
  <gazebo>
    <plugin filename="libgazebo_ros_control.so" name="ros_control">
      <robotNamespace>/</robotNamespace>
      <controlPeriod>0.001</controlPeriod>
      <robotSimType>gazebo_ros_control/DefaultRobotHWSim</robotSimType>
    </plugin>
  </gazebo>
  <!-- ############## Gazebo ####################### -->
  <!-- ################################################# -->
  <!-- #################### MiR100 ##################### -->
</robot>

