<?xml version="1.0" ?>
<!-- =================================================================================== -->
<!-- |    This document was autogenerated by xacro from /home/sevag/ur_ws/src/DORA/ur10_arm/urdf/ur10_arm.xacro | -->
<!-- |    EDITING THIS FILE BY HAND IS NOT RECOMMENDED                                 | -->
<!-- =================================================================================== -->
<robot name="ur10_arm">
  <!-- #################### Materials #################### -->
  <!-- ################################################### -->
  <!-- ################################################### -->
  <!-- #################### Materials #################### -->
  <!-- ############# Shapes Inertials with Origin ############# -->
  <!-- ######################################################## -->
  <!-- ######################################################## -->
  <!-- ############# Shapes Inertials with Origin ############# -->
  <!-- ################# Properties ################ -->
  <!-- ############################################# -->
  <!-- measured from model -->
  <!-- ############################################# -->
  <!-- ################# Properties ################ -->
  <!-- #################### Macros ################### -->
  <!-- ############################################### -->
  <!-- ############################################### -->
  <!-- #################### Macros ################### -->
  <!-- ############## Macros ################## -->
  <!-- ######################################## -->
  <!-- ######################################## -->
  <!-- ############## Macros ################## -->
  <!-- ############## Macros ################## -->
  <!-- ######################################## -->
  <!-- ######################################## -->
  <!-- ############## Macros ################## -->
  <link name="world"/>
  <!-- #################### UR10 Arm ################### -->
  <!-- ################################################# -->
  <!-- #################### URDF ################### -->
  <joint name="UR10_base_joint_fixed" type="fixed">
    <origin rpy="0.0 0.0 0.0" xyz="0.15 0.0 0.352"/>
    <parent link="world"/>
    <child link="UR10_base_link"/>
  </joint>
  <link name="UR10_base_link">
    <visual>
      <geometry>
        <mesh filename="package://ur10_arm/mesh/visual/base.dae"/>
      </geometry>
      <material name="LightGrey">
        <color rgba="0.7 0.7 0.7 1.0"/>
      </material>
    </visual>
    <collision>
      <geometry>
        <mesh filename="package://ur10_arm/mesh/collision/base.stl"/>
      </geometry>
    </collision>
    <inertial>
      <mass value="4.0"/>
      <origin rpy="0 0 0" xyz="0.0 0.0 0.0"/>
      <inertia ixx="0.0061063308908" ixy="0.0" ixz="0.0" iyy="0.0061063308908" iyz="0.0" izz="0.01125"/>
    </inertial>
  </link>
  <joint name="UR10__base_to_shoulder_pan_joint" type="revolute">
    <parent link="UR10_base_link"/>
    <child link="UR10_shoulder_pan_link"/>
    <origin rpy="0.0 0.0 0.0" xyz="0.0 0.0 0.1273"/>
    <axis xyz="0 0 1"/>
    <limit effort="330.0" lower="-3.141592653589793" upper="3.141592653589793" velocity="2.16"/>
    <dynamics damping="0.0" friction="0.0"/>
  </joint>
  <link name="UR10_shoulder_pan_link">
    <visual>
      <geometry>
        <mesh filename="package://ur10_arm/mesh/visual/shoulder.dae"/>
      </geometry>
      <material name="LightGrey">
        <color rgba="0.7 0.7 0.7 1.0"/>
      </material>
    </visual>
    <collision>
      <geometry>
        <mesh filename="package://ur10_arm/mesh/collision/shoulder.stl"/>
      </geometry>
    </collision>
    <inertial>
      <mass value="7.778"/>
      <origin rpy="0 0 0" xyz="0.0 0.0 0.0"/>
      <inertia ixx="0.03147431257693659" ixy="0.0" ixz="0.0" iyy="0.03147431257693659" iyz="0.0" izz="0.021875624999999996"/>
    </inertial>
  </link>
  <joint name="UR10__shoulder_pan_to_upper_arm_joint" type="revolute">
    <parent link="UR10_shoulder_pan_link"/>
    <child link="UR10_upper_arm_link"/>
    <origin rpy="0.0 0.0 0.0" xyz="0.0 0.220941 0.0"/>
    <axis xyz="0 1 0"/>
    <limit effort="330.0" lower="-3.141592653589793" upper="3.141592653589793" velocity="2.16"/>
    <dynamics damping="0.0" friction="0.0"/>
  </joint>
  <link name="UR10_upper_arm_link">
    <visual>
      <geometry>
        <mesh filename="package://ur10_arm/mesh/visual/upperarm.dae"/>
      </geometry>
      <material name="LightGrey">
        <color rgba="0.7 0.7 0.7 1.0"/>
      </material>
    </visual>
    <collision>
      <geometry>
        <mesh filename="package://ur10_arm/mesh/collision/upperarm.stl"/>
      </geometry>
    </collision>
    <inertial>
      <mass value="12.93"/>
      <origin rpy="0 0 0" xyz="0.0 -0.045 0.306"/>
      <inertia ixx="0.42175380379841093" ixy="0.0" ixz="0.0" iyy="0.42175380379841093" iyz="0.0" izz="0.03636562499999999"/>
    </inertial>
  </link>
  <joint name="UR10__upper_arm_to_fore_arm_joint" type="revolute">
    <parent link="UR10_upper_arm_link"/>
    <child link="UR10_fore_arm_link"/>
    <origin rpy="0.0 0.0 0.0" xyz="0.0 -0.1719 0.612"/>
    <axis xyz="0 1 0"/>
    <limit effort="150.0" lower="-3.141592653589793" upper="3.141592653589793" velocity="3.15"/>
    <dynamics damping="0.0" friction="0.0"/>
  </joint>
  <link name="UR10_fore_arm_link">
    <visual>
      <geometry>
        <mesh filename="package://ur10_arm/mesh/visual/forearm.dae"/>
      </geometry>
      <material name="LightGrey">
        <color rgba="0.7 0.7 0.7 1.0"/>
      </material>
    </visual>
    <collision>
      <geometry>
        <mesh filename="package://ur10_arm/mesh/collision/forearm.stl"/>
      </geometry>
    </collision>
    <inertial>
      <mass value="3.87"/>
      <origin rpy="0 0 0" xyz="0.0 0.0 0.28615"/>
      <inertia ixx="0.11106969409710458" ixy="0.0" ixz="0.0" iyy="0.11106969409710458" iyz="0.0" izz="0.010884375"/>
    </inertial>
  </link>
  <joint name="UR10__fore_arm_to_wrist_1_joint" type="revolute">
    <parent link="UR10_fore_arm_link"/>
    <child link="UR10_wrist_1_link"/>
    <origin rpy="0.0 0.0 0.0" xyz="0.0 0.0 0.5723"/>
    <axis xyz="0 1 0"/>
    <limit effort="54.0" lower="-3.141592653589793" upper="3.141592653589793" velocity="3.2"/>
    <dynamics damping="0.0" friction="0.0"/>
  </joint>
  <link name="UR10_wrist_1_link">
    <visual>
      <geometry>
        <mesh filename="package://ur10_arm/mesh/visual/wrist1.dae"/>
      </geometry>
      <material name="LightGrey">
        <color rgba="0.7 0.7 0.7 1.0"/>
      </material>
    </visual>
    <collision>
      <geometry>
        <mesh filename="package://ur10_arm/mesh/collision/wrist1.stl"/>
      </geometry>
    </collision>
    <inertial>
      <mass value="1.96"/>
      <origin rpy="0 0 0" xyz="0.0 0.1149 0.0"/>
      <inertia ixx="0.005108247956699999" ixy="0.0" ixz="0.0" iyy="0.005108247956699999" iyz="0.0" izz="0.005512499999999999"/>
    </inertial>
  </link>
  <joint name="UR10__wrist_1_to_wrist_2_joint" type="revolute">
    <parent link="UR10_wrist_1_link"/>
    <child link="UR10_wrist_2_link"/>
    <origin rpy="0.0 0.0 -1.5707963267948966" xyz="0.0 0.1149 0.0"/>
    <axis xyz="0 0 1"/>
    <limit effort="54.0" lower="-3.141592653589793" upper="3.141592653589793" velocity="3.2"/>
    <dynamics damping="0.0" friction="0.0"/>
  </joint>
  <link name="UR10_wrist_2_link">
    <visual>
      <geometry>
        <mesh filename="package://ur10_arm/mesh/visual/wrist2.dae"/>
      </geometry>
      <material name="LightGrey">
        <color rgba="0.7 0.7 0.7 1.0"/>
      </material>
    </visual>
    <collision>
      <geometry>
        <mesh filename="package://ur10_arm/mesh/collision/wrist2.stl"/>
      </geometry>
    </collision>
    <inertial>
      <mass value="1.96"/>
      <origin rpy="0 0 0" xyz="0.0 0.0 0.1157"/>
      <inertia ixx="0.005108247956699999" ixy="0.0" ixz="0.0" iyy="0.005108247956699999" iyz="0.0" izz="0.005512499999999999"/>
    </inertial>
  </link>
  <joint name="UR10__wrist_2_to_wrist_3_joint" type="revolute">
    <parent link="UR10_wrist_2_link"/>
    <child link="UR10_wrist_3_link"/>
    <origin rpy="0.0 0.0 0.0" xyz="0.0 0.0 0.1157"/>
    <axis xyz="0 1 0"/>
    <limit effort="54.0" lower="-3.141592653589793" upper="3.141592653589793" velocity="3.2"/>
    <dynamics damping="0.0" friction="0.0"/>
  </joint>
  <link name="UR10_wrist_3_link">
    <visual>
      <geometry>
        <mesh filename="package://ur10_arm/mesh/visual/wrist3.dae"/>
      </geometry>
      <material name="LightGrey">
        <color rgba="0.7 0.7 0.7 1.0"/>
      </material>
    </visual>
    <collision>
      <geometry>
        <mesh filename="package://ur10_arm/mesh/collision/wrist3.stl"/>
      </geometry>
    </collision>
    <inertial>
      <mass value="0.202"/>
      <origin rpy="1.5707963267948966 0 0" xyz="0.0 0.07695 0.0"/>
      <inertia ixx="0.00011792166116465" ixy="0.0" ixz="0.0" iyy="0.00011792166116465" iyz="0.0" izz="0.00020452500000000002"/>
    </inertial>
  </link>
  <joint name="UR10__wrist_3_to_end_effector_joint_fixed" type="fixed">
    <parent link="UR10_wrist_3_link"/>
    <child link="UR10_end_effector_link"/>
    <origin rpy="0.0 0.0 1.5707963267948966" xyz="0.0 0.0922 0.0"/>
  </joint>
  <link name="UR10_end_effector_link">
    <collision>
      <geometry>
        <box size="0.01 0.01 0.01"/>
      </geometry>
      <origin rpy="0 0 0" xyz="0 0 0"/>
    </collision>
  </link>
  <!-- #################### URDF ################### -->
  
  <!-- ############## Gazebo ####################### -->
  <!-- ################################################# -->
  <!-- #################### UR10 Arm ################### -->
</robot>

