<?xml version="1.0" ?>
<!-- =================================================================================== -->
<!-- |    This document was autogenerated by xacro from dora.xacro                     | -->
<!-- |    EDITING THIS FILE BY HAND IS NOT RECOMMENDED                                 | -->
<!-- =================================================================================== -->
<robot name="dora">
  <!-- #################### Materials #################### -->
  <!-- ################################################### -->
  <!-- ################################################### -->
  <!-- #################### Materials #################### -->
  <!-- ############# Shapes Inertials with Origin ############# -->
  <!-- ######################################################## -->
  <!-- ######################################################## -->
  <!-- ############# Shapes Inertials with Origin ############# -->
  <!-- ################# Properties ################ -->
  <!-- ############################################# -->
  <!-- measured from model -->
  <!-- ############################################# -->
  <!-- ################# Properties ################ -->
  <!-- #################### Macros ################### -->
  <!-- ############################################### -->
  <!-- ############################################### -->
  <!-- #################### Macros ################### -->
  <!-- ############## Macros ################## -->
  <!-- ######################################## -->
  <!-- ######################################## -->
  <!-- ############## Macros ################## -->
  <!-- ############## Macros ################## -->
  <!-- ######################################## -->
  <!-- ######################################## -->
  <!-- ############## Macros ################## -->
  <!-- ################# Properties ################ -->
  <!-- ############################################# -->
  <!-- ############################################# -->
  <!-- ################# Properties ################ -->
  <!-- #################### Macros ################### -->
  <!-- ############################################### -->
  <!-- ############################################### -->
  <!-- #################### Macros ################### -->
  <!-- ############## Macros ################## -->
  <!-- ######################################## -->
  <!-- ######################################## -->
  <!-- ############## Macros ################## -->
  <!-- ############## Macros ################## -->
  <!-- ######################################## -->
  <!-- These are to publish the state of the unactuated 
            joints, the caster wheels. -->
  <gazebo>
    <plugin filename="libgazebo_ros_joint_state_publisher.so" name="joint_state_publisher">
      <robotNamespace>/</robotNamespace>
      <jointName> MiR__base_fl_caster_rotation_joint, MiR__base_fl_caster_wheel_joint,
                                MiR__base_fr_caster_rotation_joint, MiR__base_fr_caster_wheel_joint,
                                MiR__base_bl_caster_rotation_joint, MiR__base_bl_caster_wheel_joint,
                                MiR__base_br_caster_rotation_joint, MiR__base_br_caster_wheel_joint</jointName>
      <updateRate>20.0</updateRate>
      <alwaysOn>true</alwaysOn>
    </plugin>
  </gazebo>
  <!-- ######################################## -->
  <!-- ############## Macros ################## -->
  <!-- ################# Properties ################ -->
  <!-- ############################################# -->
  <!-- ############################################# -->
  <!-- ################# Properties ################ -->
  <!-- #################### Macros ################### -->
  <!-- #################################################### -->
  <!-- #################################################### -->
  <!-- #################### Macros ################### -->
  <!-- ############## Macros ################## -->
  <!-- ######################################## -->
  <!-- ######################################## -->
  <!-- ############## Macros ################## -->
  <!-- ############## Macros ################## -->
  <!-- ######################################## -->
  <!-- ######################################## -->
  <!-- ############## Macros ################## -->
  <gazebo>
    <plugin filename="libgazebo_ros_control.so" name="ros_control">
      <robotNamespace>/</robotNamespace>
      <controlPeriod>0.001</controlPeriod>
      <robotSimType>gazebo_ros_control/DefaultRobotHWSim</robotSimType>
    </plugin>
  </gazebo>
  <link name="MiR_footprint"/>
  <!-- #################### MiR100 ##################### -->
  <!-- ################################################# -->
  <!-- #################### URDF ################### -->
  <joint name="MiR__base_joint_fixed" type="fixed">
    <parent link="MiR_footprint"/>
    <child link="MiR_base_link"/>
    <origin rpy="0 0 0" xyz="0 0 0"/>
  </joint>
  <link name="MiR_base_link">
    <inertial>
      <mass value="58.0"/>
      <origin rpy="0 0 0" xyz="0.037646 0 0.20"/>
      <inertia ixx="2.0609325089599997" ixy="0.0" ixz="0.0" iyy="4.34999826" iyz="0.0" izz="5.54093111696"/>
    </inertial>
    <visual>
      <origin rpy="0 0 0" xyz="0.037646 0 0"/>
      <geometry>
        <mesh filename="package://mir100_mobile_base/mesh/visual/mir_100_base.stl"/>
      </geometry>
      <material name="white">
        <color rgba="1 1 1 1"/>
      </material>
    </visual>
    <collision>
      <origin rpy="0 0 0" xyz="0.037646 0 0"/>
      <geometry>
        <mesh filename="package://mir100_mobile_base/mesh/collision/mir_100_base.stl"/>
      </geometry>
    </collision>
  </link>
  <joint name="MiR__base_left_wheel_joint" type="continuous">
    <origin rpy="0 0 0" xyz="0.0 0.222604 0.0625"/>
    <parent link="MiR_base_link"/>
    <child link="MiR_left_wheel_link"/>
    <axis xyz="0 1 0"/>
    <limit effort="100" velocity="20.0"/>
  </joint>
  <link name="MiR_left_wheel_link">
    <inertial>
      <mass value="1.0"/>
      <origin rpy="1.5707963267948966 0 0" xyz="0 0 0"/>
      <inertia ixx="0.001061895408575" ixy="0.0" ixz="0.0" iyy="0.001061895408575" iyz="0.0" izz="0.001953125"/>
    </inertial>
    <visual>
      <origin rpy="0 0 0" xyz="0 0 0"/>
      <geometry>
        <mesh filename="package://mir100_mobile_base/mesh/visual/wheel.stl"/>
      </geometry>
      <material name="dark_grey">
        <color rgba="0.3 0.3 0.3 1"/>
      </material>
    </visual>
    <collision>
      <origin rpy="0 0 0" xyz="0 0 0"/>
      <geometry>
        <mesh filename="package://mir100_mobile_base/mesh/visual/wheel.stl"/>
      </geometry>
    </collision>
  </link>
  <joint name="MiR__base_right_wheel_joint" type="continuous">
    <origin rpy="0 0 0" xyz="0.0 -0.222604 0.0625"/>
    <parent link="MiR_base_link"/>
    <child link="MiR_right_wheel_link"/>
    <axis xyz="0 1 0"/>
    <limit effort="100" velocity="20.0"/>
  </joint>
  <link name="MiR_right_wheel_link">
    <inertial>
      <mass value="1.0"/>
      <origin rpy="1.5707963267948966 0 0" xyz="0 0 0"/>
      <inertia ixx="0.001061895408575" ixy="0.0" ixz="0.0" iyy="0.001061895408575" iyz="0.0" izz="0.001953125"/>
    </inertial>
    <visual>
      <origin rpy="0 0 0" xyz="0 0 0"/>
      <geometry>
        <mesh filename="package://mir100_mobile_base/mesh/visual/wheel.stl"/>
      </geometry>
      <material name="dark_grey">
        <color rgba="0.3 0.3 0.3 1"/>
      </material>
    </visual>
    <collision>
      <origin rpy="0 0 0" xyz="0 0 0"/>
      <geometry>
        <mesh filename="package://mir100_mobile_base/mesh/visual/wheel.stl"/>
      </geometry>
    </collision>
  </link>
  <joint name="MiR__base_fl_caster_rotation_joint" type="continuous">
    <origin rpy="0 0 0" xyz="0.341346 0.203 0.1565"/>
    <parent link="MiR_base_link"/>
    <child link="MiR_fl_caster_rotation_link"/>
    <axis xyz="0 0 1"/>
    <dynamics damping="0.01" friction="0.0"/>
  </joint>
  <link name="MiR_fl_caster_rotation_link">
    <inertial>
      <!-- <origin xyz="0 0 -0.042500000044" rpy="${0.5 * pi} ${24 * deg_to_rad} ${1.5 * pi}" /> -->
      <origin rpy="0.41887903200000004 0 1.5707963267948966 " xyz="0 0 -0.042500000044"/>
      <mass value="0.3097539019"/>
      <inertia ixx="0.0005844517978" ixy="0" ixz="0" iyy="0.00052872551237" iyz="0" izz="0.00017923555074"/>
    </inertial>
    <visual>
      <origin rpy="0 0 0" xyz="0 0 0"/>
      <geometry>
        <mesh filename="package://mir100_mobile_base/mesh/visual/caster_wheel_base.stl"/>
      </geometry>
      <material name="silver">
        <color rgba="0.79 0.82 0.93 1"/>
      </material>
    </visual>
    <collision>
      <origin rpy="0 0 0" xyz="0 0 0"/>
      <geometry>
        <mesh filename="package://mir100_mobile_base/mesh/collision/caster_wheel_base.stl"/>
      </geometry>
    </collision>
  </link>
  <joint name="MiR__base_fl_caster_wheel_joint" type="continuous">
    <origin rpy="0 0 0" xyz="-0.0382 0 -0.094"/>
    <parent link="MiR_fl_caster_rotation_link"/>
    <child link="MiR_fl_caster_wheel_link"/>
    <axis xyz="0 1 0"/>
  </joint>
  <link name="MiR_fl_caster_wheel_link">
    <inertial>
      <mass value="1.0"/>
      <origin rpy="1.5707963267948966 0 0" xyz="0 0 0"/>
      <inertia ixx="0.001061895408575" ixy="0.0" ixz="0.0" iyy="0.001061895408575" iyz="0.0" izz="0.001953125"/>
    </inertial>
    <visual>
      <origin rpy="0 0 0" xyz="0 0 0"/>
      <geometry>
        <mesh filename="package://mir100_mobile_base/mesh/visual/wheel.stl"/>
      </geometry>
      <material name="dark_grey">
        <color rgba="0.3 0.3 0.3 1"/>
      </material>
    </visual>
    <collision>
      <origin rpy="0 0 0" xyz="0 0 0"/>
      <geometry>
        <mesh filename="package://mir100_mobile_base/mesh/visual/wheel.stl"/>
      </geometry>
    </collision>
  </link>
  <joint name="MiR__base_fr_caster_rotation_joint" type="continuous">
    <origin rpy="0 0 0" xyz="0.341346 -0.203 0.1565"/>
    <parent link="MiR_base_link"/>
    <child link="MiR_fr_caster_rotation_link"/>
    <axis xyz="0 0 1"/>
    <dynamics damping="0.01" friction="0.0"/>
  </joint>
  <link name="MiR_fr_caster_rotation_link">
    <inertial>
      <!-- <origin xyz="0 0 -0.042500000044" rpy="${0.5 * pi} ${24 * deg_to_rad} ${1.5 * pi}" /> -->
      <origin rpy="0.41887903200000004 0 1.5707963267948966 " xyz="0 0 -0.042500000044"/>
      <mass value="0.3097539019"/>
      <inertia ixx="0.0005844517978" ixy="0" ixz="0" iyy="0.00052872551237" iyz="0" izz="0.00017923555074"/>
    </inertial>
    <visual>
      <origin rpy="0 0 0" xyz="0 0 0"/>
      <geometry>
        <mesh filename="package://mir100_mobile_base/mesh/visual/caster_wheel_base.stl"/>
      </geometry>
      <material name="silver">
        <color rgba="0.79 0.82 0.93 1"/>
      </material>
    </visual>
    <collision>
      <origin rpy="0 0 0" xyz="0 0 0"/>
      <geometry>
        <mesh filename="package://mir100_mobile_base/mesh/collision/caster_wheel_base.stl"/>
      </geometry>
    </collision>
  </link>
  <joint name="MiR__base_fr_caster_wheel_joint" type="continuous">
    <origin rpy="0 0 0" xyz="-0.0382 0 -0.094"/>
    <parent link="MiR_fr_caster_rotation_link"/>
    <child link="MiR_fr_caster_wheel_link"/>
    <axis xyz="0 1 0"/>
  </joint>
  <link name="MiR_fr_caster_wheel_link">
    <inertial>
      <mass value="1.0"/>
      <origin rpy="1.5707963267948966 0 0" xyz="0 0 0"/>
      <inertia ixx="0.001061895408575" ixy="0.0" ixz="0.0" iyy="0.001061895408575" iyz="0.0" izz="0.001953125"/>
    </inertial>
    <visual>
      <origin rpy="0 0 0" xyz="0 0 0"/>
      <geometry>
        <mesh filename="package://mir100_mobile_base/mesh/visual/wheel.stl"/>
      </geometry>
      <material name="dark_grey">
        <color rgba="0.3 0.3 0.3 1"/>
      </material>
    </visual>
    <collision>
      <origin rpy="0 0 0" xyz="0 0 0"/>
      <geometry>
        <mesh filename="package://mir100_mobile_base/mesh/visual/wheel.stl"/>
      </geometry>
    </collision>
  </link>
  <joint name="MiR__base_bl_caster_rotation_joint" type="continuous">
    <origin rpy="0 0 0" xyz="-0.270154 0.203 0.1565"/>
    <parent link="MiR_base_link"/>
    <child link="MiR_bl_caster_rotation_link"/>
    <axis xyz="0 0 1"/>
    <dynamics damping="0.01" friction="0.0"/>
  </joint>
  <link name="MiR_bl_caster_rotation_link">
    <inertial>
      <!-- <origin xyz="0 0 -0.042500000044" rpy="${0.5 * pi} ${24 * deg_to_rad} ${1.5 * pi}" /> -->
      <origin rpy="0.41887903200000004 0 1.5707963267948966 " xyz="0 0 -0.042500000044"/>
      <mass value="0.3097539019"/>
      <inertia ixx="0.0005844517978" ixy="0" ixz="0" iyy="0.00052872551237" iyz="0" izz="0.00017923555074"/>
    </inertial>
    <visual>
      <origin rpy="0 0 0" xyz="0 0 0"/>
      <geometry>
        <mesh filename="package://mir100_mobile_base/mesh/visual/caster_wheel_base.stl"/>
      </geometry>
      <material name="silver">
        <color rgba="0.79 0.82 0.93 1"/>
      </material>
    </visual>
    <collision>
      <origin rpy="0 0 0" xyz="0 0 0"/>
      <geometry>
        <mesh filename="package://mir100_mobile_base/mesh/collision/caster_wheel_base.stl"/>
      </geometry>
    </collision>
  </link>
  <joint name="MiR__base_bl_caster_wheel_joint" type="continuous">
    <origin rpy="0 0 0" xyz="-0.0382 0 -0.094"/>
    <parent link="MiR_bl_caster_rotation_link"/>
    <child link="MiR_bl_caster_wheel_link"/>
    <axis xyz="0 1 0"/>
  </joint>
  <link name="MiR_bl_caster_wheel_link">
    <inertial>
      <mass value="1.0"/>
      <origin rpy="1.5707963267948966 0 0" xyz="0 0 0"/>
      <inertia ixx="0.001061895408575" ixy="0.0" ixz="0.0" iyy="0.001061895408575" iyz="0.0" izz="0.001953125"/>
    </inertial>
    <visual>
      <origin rpy="0 0 0" xyz="0 0 0"/>
      <geometry>
        <mesh filename="package://mir100_mobile_base/mesh/visual/wheel.stl"/>
      </geometry>
      <material name="dark_grey">
        <color rgba="0.3 0.3 0.3 1"/>
      </material>
    </visual>
    <collision>
      <origin rpy="0 0 0" xyz="0 0 0"/>
      <geometry>
        <mesh filename="package://mir100_mobile_base/mesh/visual/wheel.stl"/>
      </geometry>
    </collision>
  </link>
  <joint name="MiR__base_br_caster_rotation_joint" type="continuous">
    <origin rpy="0 0 0" xyz="-0.270154 -0.203 0.1565"/>
    <parent link="MiR_base_link"/>
    <child link="MiR_br_caster_rotation_link"/>
    <axis xyz="0 0 1"/>
    <dynamics damping="0.01" friction="0.0"/>
  </joint>
  <link name="MiR_br_caster_rotation_link">
    <inertial>
      <!-- <origin xyz="0 0 -0.042500000044" rpy="${0.5 * pi} ${24 * deg_to_rad} ${1.5 * pi}" /> -->
      <origin rpy="0.41887903200000004 0 1.5707963267948966 " xyz="0 0 -0.042500000044"/>
      <mass value="0.3097539019"/>
      <inertia ixx="0.0005844517978" ixy="0" ixz="0" iyy="0.00052872551237" iyz="0" izz="0.00017923555074"/>
    </inertial>
    <visual>
      <origin rpy="0 0 0" xyz="0 0 0"/>
      <geometry>
        <mesh filename="package://mir100_mobile_base/mesh/visual/caster_wheel_base.stl"/>
      </geometry>
      <material name="silver">
        <color rgba="0.79 0.82 0.93 1"/>
      </material>
    </visual>
    <collision>
      <origin rpy="0 0 0" xyz="0 0 0"/>
      <geometry>
        <mesh filename="package://mir100_mobile_base/mesh/collision/caster_wheel_base.stl"/>
      </geometry>
    </collision>
  </link>
  <joint name="MiR__base_br_caster_wheel_joint" type="continuous">
    <origin rpy="0 0 0" xyz="-0.0382 0 -0.094"/>
    <parent link="MiR_br_caster_rotation_link"/>
    <child link="MiR_br_caster_wheel_link"/>
    <axis xyz="0 1 0"/>
  </joint>
  <link name="MiR_br_caster_wheel_link">
    <inertial>
      <mass value="1.0"/>
      <origin rpy="1.5707963267948966 0 0" xyz="0 0 0"/>
      <inertia ixx="0.001061895408575" ixy="0.0" ixz="0.0" iyy="0.001061895408575" iyz="0.0" izz="0.001953125"/>
    </inertial>
    <visual>
      <origin rpy="0 0 0" xyz="0 0 0"/>
      <geometry>
        <mesh filename="package://mir100_mobile_base/mesh/visual/wheel.stl"/>
      </geometry>
      <material name="dark_grey">
        <color rgba="0.3 0.3 0.3 1"/>
      </material>
    </visual>
    <collision>
      <origin rpy="0 0 0" xyz="0 0 0"/>
      <geometry>
        <mesh filename="package://mir100_mobile_base/mesh/visual/wheel.stl"/>
      </geometry>
    </collision>
  </link>
  <joint name="MiR__base_to_surface_joint_fixed" type="fixed">
    <origin rpy="0 0 0" xyz="0.037646 0 0.352"/>
    <parent link="MiR_base_link"/>
    <child link="MiR_surface"/>
    <axis xyz="0 0 1"/>
  </joint>
  <link name="MiR_surface"/>
  <!-- IMU -->
  <joint name="MiR__base_to_imu_joint_fixed" type="fixed">
    <parent link="MiR_base_link"/>
    <child link="MiR_imu_link"/>
    <origin rpy="0 0 0" xyz="0.0 0.0 0.25"/>
    <!-- same as real MiR -->
  </joint>
  <link name="MiR_imu_link"/>
  <!-- Create an alias for imu_link. This is necessary because the real MiR's
                    TF has imu_link, but the imu_data topic is published in the imu_frame
                    frame. -->
  <joint name="MiR__imu_link_to_imu_frame_joint_fixed" type="fixed">
    <parent link="MiR_imu_link"/>
    <child link="MiR_imu_frame"/>
    <origin rpy="0 0 0" xyz="0 0 0"/>
  </joint>
  <link name="MiR_imu_frame"/>
  <!-- Laser scanners -->
  <link name="MiR_front_laser_link">
    <visual>
      <origin rpy="3.141592653589793 0 0" xyz="0.0 0.0 0.0"/>
      <geometry>
        <mesh filename="package://mir100_mobile_base/mesh/visual/sick_lms-100.stl"/>
      </geometry>
      <material name="black">
        <color rgba="0.1 0.1 0.1 1"/>
      </material>
    </visual>
    <collision>
      <origin rpy="3.141592653589793 0 0" xyz="0.0 0.0 0.0"/>
      <geometry>
        <mesh filename="package://mir100_mobile_base/mesh/visual/sick_lms-100.stl"/>
      </geometry>
    </collision>
    <inertial>
      <mass value="2.0"/>
      <origin xyz="0 0 0"/>
      <inertia ixx="0.009708329449999999" ixy="0.0" ixz="0.0" iyy="0.0097601627626" iyz="0.0" izz="0.0080601634426"/>
    </inertial>
  </link>
  <joint name="MiR__base_to_front_laser_joint_fixed" type="fixed">
    <parent link="MiR_base_link"/>
    <child link="MiR_front_laser_link"/>
    <origin rpy="0.0 0.0 0.7853981633974483" xyz="0.4288 0.2358 0.1914"/>
    <!-- from visually matching up the meshes of the MiR and the laser scanner -->
  </joint>
  <link name="MiR_back_laser_link">
    <visual>
      <origin rpy="3.141592653589793 0 0" xyz="0.0 0.0 0.0"/>
      <geometry>
        <mesh filename="package://mir100_mobile_base/mesh/visual/sick_lms-100.stl"/>
      </geometry>
      <material name="black">
        <color rgba="0.1 0.1 0.1 1"/>
      </material>
    </visual>
    <collision>
      <origin rpy="3.141592653589793 0 0" xyz="0.0 0.0 0.0"/>
      <geometry>
        <mesh filename="package://mir100_mobile_base/mesh/visual/sick_lms-100.stl"/>
      </geometry>
    </collision>
    <inertial>
      <mass value="2.0"/>
      <origin xyz="0 0 0"/>
      <inertia ixx="0.009708329449999999" ixy="0.0" ixz="0.0" iyy="0.0097601627626" iyz="0.0" izz="0.0080601634426"/>
    </inertial>
  </link>
  <joint name="Mir__base_to_back_laser_joint_fixed" type="fixed">
    <parent link="MiR_base_link"/>
    <child link="MiR_back_laser_link"/>
    <origin rpy="0.0 0.0 -2.356194490192345" xyz="-0.3548 -0.2352 0.1914"/>
    <!-- from visually matching up the meshes of the MiR and the laser scanner -->
  </joint>
  <!-- Ultrasound sensors -->
  <link name="MiR_right_us_frame"/>
  <joint name="MiR__base_to_right_us_joint_fixed" type="fixed">
    <parent link="MiR_base_link"/>
    <child link="MiR_right_us_frame"/>
    <origin rpy="0 0 0" xyz="0.45 -0.12 0.16 "/>
    <!-- from visually matching to the mesh of the MiR -->
  </joint>
  <link name="MiR_left_us_frame"/>
  <joint name="MiR__base_to_left_us_joint_fixed" type="fixed">
    <parent link="MiR_base_link"/>
    <child link="MiR_left_us_frame"/>
    <origin rpy="0 0 0" xyz="0.45 0.12 0.16 "/>
    <!-- from visually matching to the mesh of the MiR -->
  </joint>
  <!-- #################### URDF ################### -->
  <!-- ############## Transmissions ################ -->
  <transmission name="MiR_left_wheel_trans">
    <type>transmission_interface/SimpleTransmission</type>
    <joint name="MiR__base_left_wheel_joint">
      <hardwareInterface>hardware_interface/VelocityJointInterface</hardwareInterface>
    </joint>
    <actuator name="MiR__base_left_wheel_motor">
      <hardwareInterface>hardware_interface/VelocityJointInterface</hardwareInterface>
      <mechanicalReduction>1</mechanicalReduction>
    </actuator>
  </transmission>
  <transmission name="MiR_right_wheel_trans">
    <type>transmission_interface/SimpleTransmission</type>
    <joint name="MiR__base_right_wheel_joint">
      <hardwareInterface>hardware_interface/VelocityJointInterface</hardwareInterface>
    </joint>
    <actuator name="MiR__base_right_wheel_motor">
      <hardwareInterface>hardware_interface/VelocityJointInterface</hardwareInterface>
      <mechanicalReduction>1</mechanicalReduction>
    </actuator>
  </transmission>
  <!-- ############## Transmissions ################ -->
  <!-- ############## Gazebo ####################### -->
  <gazebo reference="MiR_left_wheel_link">
    <mu1 value="200"/>
    <mu2 value="200"/>
    <kp value="10000000.0"/>
    <kd value="1.0"/>
    <minDepth>0.01</minDepth>
  </gazebo>
  <gazebo reference="MiR_right_wheel_link">
    <mu1 value="200"/>
    <mu2 value="200"/>
    <kp value="10000000.0"/>
    <kd value="1.0"/>
    <minDepth>0.01</minDepth>
  </gazebo>
  <gazebo reference="MiR_fl_caster_wheel_link">
    <mu1 value="1"/>
    <mu2 value="1"/>
    <kp value="10000000.0"/>
    <kd value="1.0"/>
    <minDepth>0.01</minDepth>
  </gazebo>
  <gazebo reference="MiR_fr_caster_wheel_link">
    <mu1 value="1"/>
    <mu2 value="1"/>
    <kp value="10000000.0"/>
    <kd value="1.0"/>
    <minDepth>0.01</minDepth>
  </gazebo>
  <gazebo reference="MiR_bl_caster_wheel_link">
    <mu1 value="1"/>
    <mu2 value="1"/>
    <kp value="10000000.0"/>
    <kd value="1.0"/>
    <minDepth>0.01</minDepth>
  </gazebo>
  <gazebo reference="MiR_br_caster_wheel_link">
    <mu1 value="1"/>
    <mu2 value="1"/>
    <kp value="10000000.0"/>
    <kd value="1.0"/>
    <minDepth>0.01</minDepth>
  </gazebo>
  <!-- <xacro:MiR_controller_plugin_gazebo left_wheel_joint="MiR__base_left_wheel_joint" right_wheel_joint="MiR__base_right_wheel_joint" wheel_separation="${wheel_separation}" wheel_radius="${wheel_radius}"/> -->
  <gazebo reference="MiR_right_wheel_link">
    <material>Gazebo/DarkGrey</material>
    <turnGravityOff>false</turnGravityOff>
    <selfCollide>true</selfCollide>
  </gazebo>
  <gazebo reference="MiR_left_wheel_link">
    <material>Gazebo/DarkGrey</material>
    <turnGravityOff>false</turnGravityOff>
    <selfCollide>true</selfCollide>
  </gazebo>
  <gazebo reference="MiR_fl_caster_rotation_link">
    <material>Gazebo/Grey</material>
    <turnGravityOff>false</turnGravityOff>
    <selfCollide>true</selfCollide>
  </gazebo>
  <gazebo reference="MiR_fr_caster_rotation_link">
    <material>Gazebo/Grey</material>
    <turnGravityOff>false</turnGravityOff>
    <selfCollide>true</selfCollide>
  </gazebo>
  <gazebo reference="MiR_bl_caster_rotation_link">
    <material>Gazebo/Grey</material>
    <turnGravityOff>false</turnGravityOff>
    <selfCollide>true</selfCollide>
  </gazebo>
  <gazebo reference="MiR_br_caster_rotation_link">
    <material>Gazebo/Grey</material>
    <turnGravityOff>false</turnGravityOff>
    <selfCollide>true</selfCollide>
  </gazebo>
  <gazebo reference="MiR_front_laser_link">
    <material>Gazebo/FlatBlack</material>
    <turnGravityOff>false</turnGravityOff>
    <selfCollide>true</selfCollide>
    <sensor name="MiR__front_lase_link" type="ray">
      <pose>0 0 0 0 0 0</pose>
      <visualize>false</visualize>
      <update_rate>12.5</update_rate>
      <ray>
        <scan>
          <horizontal>
            <samples>541</samples>
            <resolution>1</resolution>
            <!-- has to be 1; actual resolution will be computed from number of samples + min_angle/max_angle -->
            <min_angle>-2.35619449615</min_angle>
            <max_angle>2.35619449615</max_angle>
          </horizontal>
        </scan>
        <range>
          <min>0.05</min>
          <max>29.0</max>
          <resolution>0.01</resolution>
        </range>
        <noise>
          <type>gaussian</type>
          <!-- Noise parameters based on published spec for S300 achieving
                                "+-29mm" accuracy at range < 3m (~0.01 of the range) at
                                1 sigma. -->
          <mean>0.0</mean>
          <stddev>0.01</stddev>
        </noise>
      </ray>
      <plugin filename="libgazebo_ros_laser.so" name="gazebo_ros_MiR__front_lase_link_controller">
        <frameName>MiR_front_laser_link</frameName>
        <topicName>/f_scan</topicName>
      </plugin>
    </sensor>
  </gazebo>
  <gazebo reference="MiR_back_laser_link">
    <material>Gazebo/FlatBlack</material>
    <turnGravityOff>false</turnGravityOff>
    <selfCollide>true</selfCollide>
    <sensor name="MiR__back_lase_link" type="ray">
      <pose>0 0 0 0 0 0</pose>
      <visualize>false</visualize>
      <update_rate>12.5</update_rate>
      <ray>
        <scan>
          <horizontal>
            <samples>541</samples>
            <resolution>1</resolution>
            <!-- has to be 1; actual resolution will be computed from number of samples + min_angle/max_angle -->
            <min_angle>-2.35619449615</min_angle>
            <max_angle>2.35619449615</max_angle>
          </horizontal>
        </scan>
        <range>
          <min>0.05</min>
          <max>29.0</max>
          <resolution>0.01</resolution>
        </range>
        <noise>
          <type>gaussian</type>
          <!-- Noise parameters based on published spec for S300 achieving
                            "+-29mm" accuracy at range < 3m (~0.01 of the range) at
                            1 sigma. -->
          <mean>0.0</mean>
          <stddev>0.01</stddev>
        </noise>
      </ray>
      <plugin filename="libgazebo_ros_laser.so" name="gazebo_ros_MiR__back_lase_link_controller">
        <frameName>MiR_back_laser_link</frameName>
        <topicName>/b_scan</topicName>
      </plugin>
    </sensor>
  </gazebo>
  <gazebo reference="MiR_base_link">
    <material>Gazebo/Grey</material>
    <turnGravityOff>false</turnGravityOff>
    <selfCollide>true</selfCollide>
  </gazebo>
  <gazebo>
    <plugin filename="libgazebo_ros_p3d.so" name="p3d_base_controller">
      <alwaysOn>true</alwaysOn>
      <updateRate>20.0</updateRate>
      <bodyName>MiR_base_link</bodyName>
      <topicName>odom_topic</topicName>
      <gaussianNoise>0.01</gaussianNoise>
      <frameName>MiR_footprint</frameName>
      <xyzOffsets>0 0 0</xyzOffsets>
      <rpyOffsets>0 0 0</rpyOffsets>
    </plugin>
  </gazebo>
  <!-- ############## Gazebo ####################### -->
  <!-- ################################################# -->
  <!-- #################### MiR100 ##################### -->
  <!-- #################### UR10 Arm ################### -->
  <!-- ################################################# -->
  <!-- #################### URDF ################### -->
  <joint name="UR10_base_joint_fixed" type="fixed">
    <origin rpy="0.0 0.0 0.0" xyz="0.15 0.0 0.352"/>
    <parent link="controlbox_top"/>
    <child link="UR10_base_link"/>
  </joint>
  <link name="UR10_base_link">
    <visual>
      <geometry>
        <mesh filename="package://ur10_arm/mesh/visual/base.dae"/>
      </geometry>
      <material name="LightGrey">
        <color rgba="0.7 0.7 0.7 1.0"/>
      </material>
    </visual>
    <collision>
      <geometry>
        <mesh filename="package://ur10_arm/mesh/collision/base.stl"/>
      </geometry>
    </collision>
    <inertial>
      <mass value="4.0"/>
      <origin rpy="0 0 0" xyz="0.0 0.0 0.0"/>
      <inertia ixx="0.0061063308908" ixy="0.0" ixz="0.0" iyy="0.0061063308908" iyz="0.0" izz="0.01125"/>
    </inertial>
  </link>
  <joint name="UR10__base_to_shoulder_pan_joint" type="revolute">
    <parent link="UR10_base_link"/>
    <child link="UR10_shoulder_pan_link"/>
    <origin rpy="0.0 0.0 0.0" xyz="0.0 0.0 0.1273"/>
    <axis xyz="0 0 1"/>
    <limit effort="330.0" lower="-3.141592653589793" upper="3.141592653589793" velocity="2.16"/>
    <dynamics damping="0.0" friction="0.0"/>
  </joint>
  <link name="UR10_shoulder_pan_link">
    <visual>
      <geometry>
        <mesh filename="package://ur10_arm/mesh/visual/shoulder.dae"/>
      </geometry>
      <material name="LightGrey">
        <color rgba="0.7 0.7 0.7 1.0"/>
      </material>
    </visual>
    <collision>
      <geometry>
        <mesh filename="package://ur10_arm/mesh/collision/shoulder.stl"/>
      </geometry>
    </collision>
    <inertial>
      <mass value="7.778"/>
      <origin rpy="0 0 0" xyz="0.0 0.0 0.0"/>
      <inertia ixx="0.03147431257693659" ixy="0.0" ixz="0.0" iyy="0.03147431257693659" iyz="0.0" izz="0.021875624999999996"/>
    </inertial>
  </link>
  <joint name="UR10__shoulder_pan_to_upper_arm_joint" type="revolute">
    <parent link="UR10_shoulder_pan_link"/>
    <child link="UR10_upper_arm_link"/>
    <origin rpy="0.0 0.0 0.0" xyz="0.0 0.220941 0.0"/>
    <axis xyz="0 1 0"/>
    <limit effort="330.0" lower="-3.141592653589793" upper="3.141592653589793" velocity="2.16"/>
    <dynamics damping="0.0" friction="0.0"/>
  </joint>
  <link name="UR10_upper_arm_link">
    <visual>
      <geometry>
        <mesh filename="package://ur10_arm/mesh/visual/upperarm.dae"/>
      </geometry>
      <material name="LightGrey">
        <color rgba="0.7 0.7 0.7 1.0"/>
      </material>
    </visual>
    <collision>
      <geometry>
        <mesh filename="package://ur10_arm/mesh/collision/upperarm.stl"/>
      </geometry>
    </collision>
    <inertial>
      <mass value="12.93"/>
      <origin rpy="0 0 0" xyz="0.0 -0.045 0.306"/>
      <inertia ixx="0.42175380379841093" ixy="0.0" ixz="0.0" iyy="0.42175380379841093" iyz="0.0" izz="0.03636562499999999"/>
    </inertial>
  </link>
  <joint name="UR10__upper_arm_to_fore_arm_joint" type="revolute">
    <parent link="UR10_upper_arm_link"/>
    <child link="UR10_fore_arm_link"/>
    <origin rpy="0.0 0.0 0.0" xyz="0.0 -0.1719 0.612"/>
    <axis xyz="0 1 0"/>
    <limit effort="150.0" lower="-3.141592653589793" upper="3.141592653589793" velocity="3.15"/>
    <dynamics damping="0.0" friction="0.0"/>
  </joint>
  <link name="UR10_fore_arm_link">
    <visual>
      <geometry>
        <mesh filename="package://ur10_arm/mesh/visual/forearm.dae"/>
      </geometry>
      <material name="LightGrey">
        <color rgba="0.7 0.7 0.7 1.0"/>
      </material>
    </visual>
    <collision>
      <geometry>
        <mesh filename="package://ur10_arm/mesh/collision/forearm.stl"/>
      </geometry>
    </collision>
    <inertial>
      <mass value="3.87"/>
      <origin rpy="0 0 0" xyz="0.0 0.0 0.28615"/>
      <inertia ixx="0.11106969409710458" ixy="0.0" ixz="0.0" iyy="0.11106969409710458" iyz="0.0" izz="0.010884375"/>
    </inertial>
  </link>
  <joint name="UR10__fore_arm_to_wrist_1_joint" type="revolute">
    <parent link="UR10_fore_arm_link"/>
    <child link="UR10_wrist_1_link"/>
    <origin rpy="0.0 0.0 0.0" xyz="0.0 0.0 0.5723"/>
    <axis xyz="0 1 0"/>
    <limit effort="54.0" lower="-3.141592653589793" upper="3.141592653589793" velocity="3.2"/>
    <dynamics damping="0.0" friction="0.0"/>
  </joint>
  <link name="UR10_wrist_1_link">
    <visual>
      <geometry>
        <mesh filename="package://ur10_arm/mesh/visual/wrist1.dae"/>
      </geometry>
      <material name="LightGrey">
        <color rgba="0.7 0.7 0.7 1.0"/>
      </material>
    </visual>
    <collision>
      <geometry>
        <mesh filename="package://ur10_arm/mesh/collision/wrist1.stl"/>
      </geometry>
    </collision>
    <inertial>
      <mass value="1.96"/>
      <origin rpy="0 0 0" xyz="0.0 0.1149 0.0"/>
      <inertia ixx="0.005108247956699999" ixy="0.0" ixz="0.0" iyy="0.005108247956699999" iyz="0.0" izz="0.005512499999999999"/>
    </inertial>
  </link>
  <joint name="UR10__wrist_1_to_wrist_2_joint" type="revolute">
    <parent link="UR10_wrist_1_link"/>
    <child link="UR10_wrist_2_link"/>
    <origin rpy="0.0 0.0 -1.5707963267948966" xyz="0.0 0.1149 0.0"/>
    <axis xyz="0 0 1"/>
    <limit effort="54.0" lower="-3.141592653589793" upper="3.141592653589793" velocity="3.2"/>
    <dynamics damping="0.0" friction="0.0"/>
  </joint>
  <link name="UR10_wrist_2_link">
    <visual>
      <geometry>
        <mesh filename="package://ur10_arm/mesh/visual/wrist2.dae"/>
      </geometry>
      <material name="LightGrey">
        <color rgba="0.7 0.7 0.7 1.0"/>
      </material>
    </visual>
    <collision>
      <geometry>
        <mesh filename="package://ur10_arm/mesh/collision/wrist2.stl"/>
      </geometry>
    </collision>
    <inertial>
      <mass value="1.96"/>
      <origin rpy="0 0 0" xyz="0.0 0.0 0.1157"/>
      <inertia ixx="0.005108247956699999" ixy="0.0" ixz="0.0" iyy="0.005108247956699999" iyz="0.0" izz="0.005512499999999999"/>
    </inertial>
  </link>
  <joint name="UR10__wrist_2_to_wrist_3_joint" type="revolute">
    <parent link="UR10_wrist_2_link"/>
    <child link="UR10_wrist_3_link"/>
    <origin rpy="0.0 0.0 0.0" xyz="0.0 0.0 0.1157"/>
    <axis xyz="0 1 0"/>
    <limit effort="54.0" lower="-3.141592653589793" upper="3.141592653589793" velocity="3.2"/>
    <dynamics damping="0.0" friction="0.0"/>
  </joint>
  <link name="UR10_wrist_3_link">
    <visual>
      <geometry>
        <mesh filename="package://ur10_arm/mesh/visual/wrist3.dae"/>
      </geometry>
      <material name="LightGrey">
        <color rgba="0.7 0.7 0.7 1.0"/>
      </material>
    </visual>
    <collision>
      <geometry>
        <mesh filename="package://ur10_arm/mesh/collision/wrist3.stl"/>
      </geometry>
    </collision>
    <inertial>
      <mass value="0.202"/>
      <origin rpy="1.5707963267948966 0 0" xyz="0.0 0.07695 0.0"/>
      <inertia ixx="0.00011792166116465" ixy="0.0" ixz="0.0" iyy="0.00011792166116465" iyz="0.0" izz="0.00020452500000000002"/>
    </inertial>
  </link>
  <joint name="UR10__wrist_3_to_end_effector_joint_fixed" type="fixed">
    <parent link="UR10_wrist_3_link"/>
    <child link="UR10_end_effector_link"/>
    <origin rpy="0.0 0.0 1.5707963267948966" xyz="0.0 0.0922 0.0"/>
  </joint>
  <link name="UR10_end_effector_link">
    <collision>
      <geometry>
        <box size="0.01 0.01 0.01"/>
      </geometry>
      <origin rpy="0 0 0" xyz="0 0 0"/>
    </collision>
  </link>
  <!-- #################### URDF ################### -->
  <!-- ############## Transmissions ################ -->
  <!-- 
                hw_interface:="hardware_interface/PositionJointInterface"
                hw_interface:="hardware_interface/EffortJointInterface" 
            -->
  <transmission name="UR10__base_to_shoulder_pan_trans">
    <type>transmission_interface/SimpleTransmission</type>
    <joint name="UR10__base_to_shoulder_pan_joint">
      <hardwareInterface>hardware_interface/PositionJointInterface</hardwareInterface>
    </joint>
    <actuator name="UR10__base_to_shoulder_pan_motor">
      <hardwareInterface>hardware_interface/PositionJointInterface</hardwareInterface>
      <mechanicalReduction>1</mechanicalReduction>
    </actuator>
  </transmission>
  <transmission name="UR10__shoulder_pan_to_upper_arm_trans">
    <type>transmission_interface/SimpleTransmission</type>
    <joint name="UR10__shoulder_pan_to_upper_arm_joint">
      <hardwareInterface>hardware_interface/PositionJointInterface</hardwareInterface>
    </joint>
    <actuator name="UR10__shoulder_pan_to_upper_arm_motor">
      <hardwareInterface>hardware_interface/PositionJointInterface</hardwareInterface>
      <mechanicalReduction>1</mechanicalReduction>
    </actuator>
  </transmission>
  <transmission name="UR10__upper_arm_to_fore_arm_trans">
    <type>transmission_interface/SimpleTransmission</type>
    <joint name="UR10__upper_arm_to_fore_arm_joint">
      <hardwareInterface>hardware_interface/PositionJointInterface</hardwareInterface>
    </joint>
    <actuator name="UR10__upper_arm_to_fore_arm_motor">
      <hardwareInterface>hardware_interface/PositionJointInterface</hardwareInterface>
      <mechanicalReduction>1</mechanicalReduction>
    </actuator>
  </transmission>
  <transmission name="UR10__fore_arm_to_wrist_1_trans">
    <type>transmission_interface/SimpleTransmission</type>
    <joint name="UR10__fore_arm_to_wrist_1_joint">
      <hardwareInterface>hardware_interface/PositionJointInterface</hardwareInterface>
    </joint>
    <actuator name="UR10__fore_arm_to_wrist_1_motor">
      <hardwareInterface>hardware_interface/PositionJointInterface</hardwareInterface>
      <mechanicalReduction>1</mechanicalReduction>
    </actuator>
  </transmission>
  <transmission name="UR10__wrist_1_to_wrist_2_trans">
    <type>transmission_interface/SimpleTransmission</type>
    <joint name="UR10__wrist_1_to_wrist_2_joint">
      <hardwareInterface>hardware_interface/PositionJointInterface</hardwareInterface>
    </joint>
    <actuator name="UR10__wrist_1_to_wrist_2_motor">
      <hardwareInterface>hardware_interface/PositionJointInterface</hardwareInterface>
      <mechanicalReduction>1</mechanicalReduction>
    </actuator>
  </transmission>
  <transmission name="UR10__wrist_2_to_wrist_3_trans">
    <type>transmission_interface/SimpleTransmission</type>
    <joint name="UR10__wrist_2_to_wrist_3_joint">
      <hardwareInterface>hardware_interface/PositionJointInterface</hardwareInterface>
    </joint>
    <actuator name="UR10__wrist_2_to_wrist_3_motor">
      <hardwareInterface>hardware_interface/PositionJointInterface</hardwareInterface>
      <mechanicalReduction>1</mechanicalReduction>
    </actuator>
  </transmission>
  <!-- ############## Transmissions ################ -->
  <!-- ############## Gazebo ####################### -->
  <gazebo reference="UR10_shoulder_pan_link">
    <turnGravityOff>false</turnGravityOff>
    <selfCollide>true</selfCollide>
  </gazebo>
  <gazebo reference="UR10_upper_arm_link">
    <turnGravityOff>false</turnGravityOff>
    <selfCollide>true</selfCollide>
  </gazebo>
  <gazebo reference="UR10_fore_arm_link">
    <turnGravityOff>false</turnGravityOff>
    <selfCollide>true</selfCollide>
  </gazebo>
  <gazebo reference="UR10_wrist_1_link">
    <turnGravityOff>false</turnGravityOff>
    <selfCollide>true</selfCollide>
  </gazebo>
  <gazebo reference="UR10_wrist_2_link">
    <turnGravityOff>false</turnGravityOff>
    <selfCollide>true</selfCollide>
  </gazebo>
  <gazebo reference="UR10_wrist_3_link">
    <turnGravityOff>false</turnGravityOff>
    <selfCollide>true</selfCollide>
  </gazebo>
  <!-- ############## Gazebo ####################### -->
  <!-- ################################################# -->
  <!-- #################### UR10 Arm ################### -->
  <!-- ################################################# -->
  <!-- ###################  Control Box ################ -->
  <!-- THIS IS WHERE THE CONNECTION HAPPENS -->
  <link name="controlbox">
    <visual>
      <origin rpy="0 0 0" xyz="0 0 0.27"/>
      <geometry>
        <box size="0.75 0.535 0.53"/>
      </geometry>
      <material name="White">
        <color rgba="1 1 1 1"/>
      </material>
    </visual>
    <collision>
      <origin rpy="0 0 0" xyz="0 0 0.27"/>
      <geometry>
        <box size="0.75 0.535 0.53"/>
      </geometry>
    </collision>
  </link>
  <joint name="mir_box_joint" type="fixed">
    <origin rpy="0 0 0" xyz="0.038 0 0.352"/>
    <parent link="MiR_base_link"/>
    <child link="controlbox"/>
  </joint>
  <link name="controlbox_top">
</link>
  <joint name="box_joint" type="fixed">
    <origin rpy="0 0 0" xyz="0 0 0.176"/>
    <parent link="controlbox"/>
    <child link="controlbox_top"/>
  </joint>
  <!-- ################################################# -->
  <!-- ###################  Control Box ################ -->
  <!-- #################### Barret Hand ################### -->
  <!-- #################################################### -->
  <!-- #################### URDF ################### -->
  <joint name="BH282_base_joint_fixed" type="fixed">
    <!-- To Attach the Gripper to the Arm -->
    <!-- Change This if you would like to run the gripper stand-alone -->
    <origin rpy="0 1.5707963267948966 0" xyz="0 0 0"/>
    <!-- <origin xyz="0 0 0" rpy="0 0 0" /> -->
    <parent link="UR10_end_effector_link"/>
    <child link="BH282_base_link"/>
  </joint>
  <link name="BH282_base_link">
    <inertial>
      <mass value="1.0"/>
      <origin xyz="0 0 0"/>
      <inertia ixx="1.0" ixy="0.0" ixz="0.0" iyy="1.0" iyz="0.0" izz="1.0"/>
    </inertial>
    <visual>
      <origin rpy="0 0 0" xyz="0 0 0"/>
      <geometry>
        <mesh filename="package://bh282_hand/mesh/palm_282.dae"/>
      </geometry>
      <color rgba="0.75 0.75 0.75 1.0"/>
    </visual>
    <collision>
      <origin rpy="0 0 0 " xyz="0 0 0"/>
      <geometry>
        <mesh filename="package://bh282_hand/mesh/palm_282.dae"/>
      </geometry>
      <contact_coefficients kd="1.0" kp="1000.0" mu="100.0"/>
    </collision>
  </link>
  <!-- Finger 1-->
  <link name="BH282_finger_11_link">
    <inertial>
      <mass value="0.1"/>
      <origin rpy="0 0 0" xyz="-0.046 0 0"/>
      <inertia ixx="0.01" ixy="0" ixz="0" iyy="0.01" iyz="0" izz="0.01"/>
    </inertial>
    <visual>
      <origin rpy="0 0 0" xyz="0 0 0"/>
      <geometry>
        <mesh filename="package://bh282_hand/mesh/knuckle.dae"/>
      </geometry>
    </visual>
    <collision>
      <origin rpy="0 0 0" xyz="0 0 0"/>
      <geometry>
        <mesh filename="package://bh282_hand/mesh/knuckle.dae"/>
      </geometry>
    </collision>
  </link>
  <joint name="BH282__base_to_finger_11_joint" type="revolute">
    <parent link="BH282_base_link"/>
    <child link="BH282_finger_11_link"/>
    <origin rpy="0 0 1.5708" xyz="-0.025 0 0.0252"/>
    <axis xyz="0 0 -1"/>
    <limit effort="30.0" lower="0" upper="3.141592653589793" velocity="2.0"/>
    <dynamics damping="0.7" friction="0.0"/>
  </joint>
  <link name="BH282_finger_12_link">
    <inertial>
      <mass value="0.1"/>
      <origin rpy="0 0 0" xyz="0 0 0"/>
      <inertia ixx="0.01" ixy="0" ixz="0" iyy="0.01" iyz="0" izz="0.01"/>
    </inertial>
    <visual>
      <origin rpy="0 0 0" xyz="0 0 0"/>
      <geometry>
        <mesh filename="package://bh282_hand/mesh/finger.dae"/>
      </geometry>
    </visual>
    <collision>
      <origin rpy="0 0 0" xyz="0 0 0"/>
      <geometry>
        <mesh filename="package://bh282_hand/mesh/finger.dae"/>
      </geometry>
      <contact_coefficients kd="1.0" kp="1000.0" mu="0"/>
    </collision>
  </link>
  <joint name="BH282__finger_11_to_finger_12_joint" type="revolute">
    <parent link="BH282_finger_11_link"/>
    <child link="BH282_finger_12_link"/>
    <origin rpy="1.5707963267948966 0 0" xyz="-0.05 0 0.0339"/>
    <axis xyz="0 0 -1"/>
    <limit effort="30.0" lower="0.0" upper="2.44" velocity="2.0"/>
    <dynamics damping="0.7" friction="0.0"/>
  </joint>
  <link name="BH282_finger_13_link">
    <inertial>
      <mass value="0.1"/>
      <origin rpy="0 0 0" xyz="0 0 0"/>
      <inertia ixx="0.01" ixy="0" ixz="0" iyy="0.01" iyz="0" izz="0.01"/>
    </inertial>
    <visual>
      <origin rpy="0 0 0" xyz="0 0 0"/>
      <geometry>
        <mesh filename="package://bh282_hand/mesh/finger_tip.dae"/>
      </geometry>
    </visual>
    <collision>
      <origin rpy="0 0 0" xyz="0 0 0"/>
      <geometry>
        <mesh filename="package://bh282_hand/mesh/finger_tip.dae"/>
      </geometry>
      <contact_coefficients kd="1.0" kp="1000.0" mu="0"/>
    </collision>
  </link>
  <joint name="BH282__finger_12_to_finger_13_joint" type="revolute">
    <parent link="BH282_finger_12_link"/>
    <child link="BH282_finger_13_link"/>
    <origin rpy="0 0 0" xyz="-0.069936 0.003 0"/>
    <axis xyz="0 0 -1"/>
    <limit effort="30.0" lower="0.0" upper="0.84" velocity="2.0"/>
    <dynamics damping="0.7" friction="0.0"/>
  </joint>
  <!-- Finger 2-->
  <link name="BH282_finger_21_link">
    <inertial>
      <mass value="0.1"/>
      <origin rpy="0 0 0" xyz="-0.046 0 0"/>
      <inertia ixx="0.01" ixy="0" ixz="0" iyy="0.01" iyz="0" izz="0.01"/>
    </inertial>
    <visual>
      <origin rpy="0 0 0" xyz="0 0 0"/>
      <geometry>
        <mesh filename="package://bh282_hand/mesh/knuckle.dae"/>
      </geometry>
    </visual>
    <collision>
      <origin rpy="0 0 0" xyz="0 0 0"/>
      <geometry>
        <mesh filename="package://bh282_hand/mesh/knuckle.dae"/>
      </geometry>
    </collision>
  </link>
  <joint name="BH282__base_to_finger_21_joint" type="revolute">
    <parent link="BH282_base_link"/>
    <child link="BH282_finger_21_link"/>
    <origin rpy="0 0 1.5707963267948966" xyz="0.025 0 0.0252"/>
    <axis xyz="0 0 1"/>
    <limit effort="30.0" lower="0" upper="3.141592653589793" velocity="2.0"/>
    <dynamics damping="0.7" friction="0.0"/>
  </joint>
  <link name="BH282_finger_22_link">
    <inertial>
      <mass value="0.1"/>
      <origin rpy="0 0 0" xyz="0 0 0"/>
      <inertia ixx="0.01" ixy="0" ixz="0" iyy="0.01" iyz="0" izz="0.01"/>
    </inertial>
    <visual>
      <origin rpy="0 0 0" xyz="0 0 0"/>
      <geometry>
        <mesh filename="package://bh282_hand/mesh/finger.dae"/>
      </geometry>
    </visual>
    <collision>
      <origin rpy="0 0 0" xyz="0 0 0"/>
      <geometry>
        <mesh filename="package://bh282_hand/mesh/finger.dae"/>
      </geometry>
      <contact_coefficients kd="1.0" kp="1000.0" mu="0"/>
    </collision>
  </link>
  <joint name="BH282__finger_21_to_finger_22_joint" type="revolute">
    <parent link="BH282_finger_21_link"/>
    <child link="BH282_finger_22_link"/>
    <origin rpy="1.5707963267948966 -8.8281E-17 0" xyz="-0.05 0 0.0339"/>
    <axis xyz="0 0 -1"/>
    <limit effort="30.0" lower="0.0" upper="2.44" velocity="2.0"/>
    <dynamics damping="0.7" friction="0.0"/>
  </joint>
  <link name="BH282_finger_23_link">
    <inertial>
      <mass value="0.1"/>
      <origin rpy="0 0 0" xyz="0 0 0"/>
      <inertia ixx="0.01" ixy="0" ixz="0" iyy="0.01" iyz="0" izz="0.01"/>
    </inertial>
    <visual>
      <origin rpy="0 0 0" xyz="0 0 0"/>
      <geometry>
        <mesh filename="package://bh282_hand/mesh/finger_tip.dae"/>
      </geometry>
    </visual>
    <collision>
      <origin rpy="0 0 0" xyz="0 0 0"/>
      <geometry>
        <mesh filename="package://bh282_hand/mesh/finger_tip.dae"/>
      </geometry>
      <contact_coefficients kd="1.0" kp="1000.0" mu="0"/>
    </collision>
  </link>
  <joint name="BH282__finger_22_to_finger_23_joint" type="revolute">
    <parent link="BH282_finger_22_link"/>
    <child link="BH282_finger_23_link"/>
    <origin rpy="0 0 0" xyz="-0.069936 0.003 0"/>
    <axis xyz="0 0 -1"/>
    <limit effort="30.0" lower="0.0" upper="0.84" velocity="2.0"/>
    <dynamics damping="0.7" friction="0.0"/>
  </joint>
  <!-- Finger 3-->
  <link name="BH282_finger_31_link">
    <inertial>
      <mass value="0.1"/>
      <origin rpy="0 0 0" xyz="-0.046 0 0"/>
      <inertia ixx="0.01" ixy="0" ixz="0" iyy="0.01" iyz="0" izz="0.01"/>
    </inertial>
    <visual>
      <origin rpy="0 0 0" xyz="-0.04 0 0"/>
      <geometry>
        <mesh filename="package://bh282_hand/mesh/knuckle_fixed.dae"/>
      </geometry>
    </visual>
    <collision>
      <origin rpy="0 0 0" xyz="-0.04 0 0"/>
      <geometry>
        <mesh filename="package://bh282_hand/mesh/knuckle_fixed.dae"/>
      </geometry>
      <contact_coefficients kd="1.0" kp="1000.0" mu="0"/>
    </collision>
  </link>
  <joint name="BH282__base_to_finger_31_joint_fixed" type="fixed">
    <parent link="BH282_base_link"/>
    <child link="BH282_finger_31_link"/>
    <origin rpy="0 0 -1.5707963267948966" xyz="0 0 0.0252"/>
  </joint>
  <link name="BH282_finger_32_link">
    <inertial>
      <mass value="0.1"/>
      <origin rpy="0 0 0" xyz="0 0 0"/>
      <inertia ixx="0.01" ixy="0" ixz="0" iyy="0.01" iyz="0" izz="0.01"/>
    </inertial>
    <visual>
      <origin rpy="0 0 0" xyz="0 0 0"/>
      <geometry>
        <mesh filename="package://bh282_hand/mesh/finger.dae"/>
      </geometry>
    </visual>
    <collision>
      <origin rpy="0 0 0" xyz="0 0 0"/>
      <geometry>
        <mesh filename="package://bh282_hand/mesh/finger.dae"/>
      </geometry>
      <contact_coefficients kd="1.0" kp="1000.0" mu="0"/>
    </collision>
  </link>
  <joint name="BH282__finger_31_to_finger_32_joint" type="revolute">
    <parent link="BH282_finger_31_link"/>
    <child link="BH282_finger_32_link"/>
    <origin rpy="1.5707963267948966 -8.8281E-17 0" xyz="-0.05 0 0.0339"/>
    <axis xyz="0 0 -1"/>
    <limit effort="30.0" lower="0.0" upper="2.44" velocity="2.0"/>
    <dynamics damping="0.7" friction="0.0"/>
  </joint>
  <link name="BH282_finger_33_link">
    <inertial>
      <mass value="0.1"/>
      <origin rpy="0 0 0" xyz="0 0 0"/>
      <inertia ixx="0.01" ixy="0" ixz="0" iyy="0.01" iyz="0" izz="0.01"/>
    </inertial>
    <visual>
      <origin rpy="0 0 0" xyz="0 0 0"/>
      <geometry>
        <mesh filename="package://bh282_hand/mesh/finger_tip.dae"/>
      </geometry>
    </visual>
    <collision>
      <origin rpy="0 0 0" xyz="0 0 0"/>
      <geometry>
        <mesh filename="package://bh282_hand/mesh/finger_tip.dae"/>
      </geometry>
      <contact_coefficients kd="1.0" kp="1000.0" mu="0"/>
    </collision>
  </link>
  <joint name="BH282__finger_32_to_finger_33_joint" type="revolute">
    <parent link="BH282_finger_32_link"/>
    <child link="BH282_finger_33_link"/>
    <origin rpy="0 0 0" xyz="-0.069936 0.003 0"/>
    <axis xyz="0 0 -1"/>
    <limit effort="30.0" lower="0.0" upper="0.84" velocity="2.0"/>
    <dynamics damping="0.7" friction="0.0"/>
  </joint>
  <!-- #################### URDF ################### -->
  <!-- ############## Transmissions ################ -->
  <!-- Finger 1-->
  <transmission name="BH282__base_to_finger_11_trans">
    <type>transmission_interface/SimpleTransmission</type>
    <joint name="BH282__base_to_finger_11_joint">
      <hardwareInterface>hardware_interface/PositionJointInterface</hardwareInterface>
    </joint>
    <actuator name="BH282__base_to_finger_11_motor">
      <hardwareInterface>hardware_interface/PositionJointInterface</hardwareInterface>
      <mechanicalReduction>1</mechanicalReduction>
      <motorTorqueConstant>1</motorTorqueConstant>
    </actuator>
  </transmission>
  <transmission name="BH282__finger_11_to_finger_12_trans">
    <type>transmission_interface/SimpleTransmission</type>
    <joint name="BH282__finger_11_to_finger_12_joint">
      <hardwareInterface>hardware_interface/PositionJointInterface</hardwareInterface>
    </joint>
    <actuator name="BH282__finger_11_to_finger_12_motor">
      <hardwareInterface>hardware_interface/PositionJointInterface</hardwareInterface>
      <mechanicalReduction>1</mechanicalReduction>
      <motorTorqueConstant>1</motorTorqueConstant>
    </actuator>
  </transmission>
  <transmission name="BH282__finger_12_to_finger_13_trans">
    <type>transmission_interface/SimpleTransmission</type>
    <joint name="BH282__finger_12_to_finger_13_joint">
      <hardwareInterface>hardware_interface/PositionJointInterface</hardwareInterface>
    </joint>
    <actuator name="BH282__finger_12_to_finger_13_motor">
      <hardwareInterface>hardware_interface/PositionJointInterface</hardwareInterface>
      <mechanicalReduction>1</mechanicalReduction>
      <motorTorqueConstant>1</motorTorqueConstant>
    </actuator>
  </transmission>
  <!-- Finger 2-->
  <transmission name="BH282__base_to_finger_21_trans">
    <type>transmission_interface/SimpleTransmission</type>
    <joint name="BH282__base_to_finger_21_joint">
      <hardwareInterface>hardware_interface/PositionJointInterface</hardwareInterface>
    </joint>
    <actuator name="BH282__base_to_finger_21_motor">
      <hardwareInterface>hardware_interface/PositionJointInterface</hardwareInterface>
      <mechanicalReduction>1</mechanicalReduction>
      <motorTorqueConstant>1</motorTorqueConstant>
    </actuator>
  </transmission>
  <transmission name="BH282__finger_21_to_finger_22_trans">
    <type>transmission_interface/SimpleTransmission</type>
    <joint name="BH282__finger_21_to_finger_22_joint">
      <hardwareInterface>hardware_interface/PositionJointInterface</hardwareInterface>
    </joint>
    <actuator name="BH282__finger_21_to_finger_22_motor">
      <hardwareInterface>hardware_interface/PositionJointInterface</hardwareInterface>
      <mechanicalReduction>1</mechanicalReduction>
      <motorTorqueConstant>1</motorTorqueConstant>
    </actuator>
  </transmission>
  <transmission name="BH282__finger_22_to_finger_23_trans">
    <type>transmission_interface/SimpleTransmission</type>
    <joint name="BH282__finger_22_to_finger_23_joint">
      <hardwareInterface>hardware_interface/PositionJointInterface</hardwareInterface>
    </joint>
    <actuator name="BH282__finger_22_to_finger_23_motor">
      <hardwareInterface>hardware_interface/PositionJointInterface</hardwareInterface>
      <mechanicalReduction>1</mechanicalReduction>
      <motorTorqueConstant>1</motorTorqueConstant>
    </actuator>
  </transmission>
  <!-- Finger 3-->
  <transmission name="BH282__finger_31_to_finger_32_trans">
    <type>transmission_interface/SimpleTransmission</type>
    <joint name="BH282__finger_31_to_finger_32_joint">
      <hardwareInterface>hardware_interface/PositionJointInterface</hardwareInterface>
    </joint>
    <actuator name="BH282__finger_31_to_finger_32_motor">
      <hardwareInterface>hardware_interface/PositionJointInterface</hardwareInterface>
      <mechanicalReduction>1</mechanicalReduction>
      <motorTorqueConstant>1</motorTorqueConstant>
    </actuator>
  </transmission>
  <transmission name="BH282__finger_32_to_finger_33_trans">
    <type>transmission_interface/SimpleTransmission</type>
    <joint name="BH282__finger_32_to_finger_33_joint">
      <hardwareInterface>hardware_interface/PositionJointInterface</hardwareInterface>
    </joint>
    <actuator name="BH282__finger_32_to_finger_33_motor">
      <hardwareInterface>hardware_interface/PositionJointInterface</hardwareInterface>
      <mechanicalReduction>1</mechanicalReduction>
      <motorTorqueConstant>1</motorTorqueConstant>
    </actuator>
  </transmission>
  <!-- ############## Transmissions ################ -->
  <!-- ############## Gazebo ####################### -->
  <gazebo reference="BH282_base_link">
    <material>Gazebo/White</material>
    <turnGravityOff>false</turnGravityOff>
    <selfCollide>true</selfCollide>
  </gazebo>
  <!-- Finger 1-->
  <gazebo reference="BH282_finger_11_link">
    <material>Gazebo/White</material>
    <turnGravityOff>false</turnGravityOff>
    <selfCollide>true</selfCollide>
  </gazebo>
  <gazebo reference="BH282_finger_12_link">
    <material>Gazebo/White</material>
    <turnGravityOff>false</turnGravityOff>
    <selfCollide>true</selfCollide>
  </gazebo>
  <gazebo reference="BH282_finger_13_link">
    <material>Gazebo/White</material>
    <turnGravityOff>false</turnGravityOff>
    <selfCollide>true</selfCollide>
  </gazebo>
  <!-- Finger 2-->
  <gazebo reference="BH282_finger_21_link">
    <material>Gazebo/White</material>
    <turnGravityOff>false</turnGravityOff>
    <selfCollide>true</selfCollide>
  </gazebo>
  <gazebo reference="BH282_finger_22_link">
    <material>Gazebo/White</material>
    <turnGravityOff>false</turnGravityOff>
    <selfCollide>true</selfCollide>
  </gazebo>
  <gazebo reference="BH282_finger_23_link">
    <material>Gazebo/White</material>
    <turnGravityOff>false</turnGravityOff>
    <selfCollide>true</selfCollide>
  </gazebo>
  <!-- Finger 2-->
  <gazebo reference="BH282_finger_31_link">
    <material>Gazebo/White</material>
    <turnGravityOff>false</turnGravityOff>
    <selfCollide>true</selfCollide>
  </gazebo>
  <gazebo reference="BH282_finger_32_link">
    <material>Gazebo/White</material>
    <turnGravityOff>false</turnGravityOff>
    <selfCollide>true</selfCollide>
  </gazebo>
  <gazebo reference="BH282_finger_33_link">
    <material>Gazebo/White</material>
    <turnGravityOff>false</turnGravityOff>
    <selfCollide>true</selfCollide>
  </gazebo>
  <!-- ############## Gazebo ####################### -->
  <!-- #################################################### -->
  <!-- #################### Barret Hand ################### -->
</robot>

